Workbook

Sheet Totals
A1: Account Category | B1: Jan | C1: Feb | D1: Mar | E1: Apr | F1: May | G1: Jun | H1: Jul | I1: Aug | J1: Sep | K1: Oct | L1: Nov | M1: Dec | N1: TOTAL | P1: Budget | Q1: Goal | R1: AVG/MONTH | S1: BUDGET AVG/MONTH
A2: 2021 Year
A4: SOS | B4: ='Revnue - Spot On Supplies 2022'!$I$34 -> 0 | C4: ='Revnue - Spot On Supplies 2022'!$J$34 -> 78.93 | D4: ='Revnue - Spot On Supplies 2022'!$K$34 -> 303.02 | E4: ='Revnue - Spot On Supplies 2022'!$L$34 -> 260.79 | F4: ='Revnue - Spot On Supplies 2022'!$M$34 -> 698.58 | G4: ='Revnue - Spot On Supplies 2022'!$N$34 -> 321.26 | H4: ='Revnue - Spot On Supplies 2022'!$O$34 -> 1160.82 | I4: ='Revnue - Spot On Supplies 2022'!$P$34 -> 325.16 | J4: ='Revnue - Spot On Supplies 2022'!$Q$34 -> 1529.58 | K4: ='Revnue - Spot On Supplies 2022'!$R$34 -> 845.82 | L4: 0 | M4: 0 | N4: ='Revnue - Spot On Supplies 2022'!$U$34 -> 5775.42 | P4: ='Revnue - Spot On Supplies 2022'!$W$34 -> 25051 | Q4: ='Revnue - Spot On Supplies 2022'!$X$34 -> 37551 | R4: ='Revnue - Spot On Supplies 2022'!$Y$34 -> 481.285 | S4: =P4/12 -> 2087.5833
A5: SOE | B5: ='SO Equipment 2022'!$I$17 -> 0 | C5: ='SO Equipment 2022'!$J$17 -> 0 | D5: ='SO Equipment 2022'!$K$17 -> 0 | E5: ='SO Equipment 2022'!$L$17 -> 0 | F5: ='SO Equipment 2022'!$M$17 -> 0 | G5: ='SO Equipment 2022'!$N$17 -> 0 | H5: ='SO Equipment 2022'!$O$17 -> 0 | I5: ='SO Equipment 2022'!$P$17 -> 0 | J5: ='SO Equipment 2022'!$Q$17 -> 0 | K5: ='SO Equipment 2022'!$R$17 -> 0 | L5: ='SO Equipment 2022'!$R$17 -> 0 | M5: ='SO Equipment 2022'!$R$17 -> 0 | N5: ='SO Equipment 2022'!$U$17 -> 0 | P5: ='SO Equipment 2022'!$W$17 -> 120000 | Q5: ='SO Equipment 2022'!$X$17 -> 240000 | R5: ='SO Equipment 2022'!$Y$17 -> 0 | S5: =P5/12 -> 10000
A6: NSO Supplies | B6: ='Revnue - NSO Supplies 2021'!$I$990 -> 3452.69 | C6: ='Revnue - NSO Supplies 2021'!$J$990 -> 11731.19 | D6: ='Revnue - NSO Supplies 2021'!$K$990 -> 26055.33 | E6: ='Revnue - NSO Supplies 2021'!$L$990 -> 32150.805 | F6: ='Revnue - NSO Supplies 2021'!$M$990 -> 15623.35 | G6: ='Revnue - NSO Supplies 2021'!$N$990 -> 24178.67 | H6: ='Revnue - NSO Supplies 2021'!$O$990 -> 19129.72 | I6: ='Revnue - NSO Supplies 2021'!$P$990 -> 17865.57 | J6: ='Revnue - NSO Supplies 2021'!$Q$990 -> 15961.28 | K6: ='Revnue - NSO Supplies 2021'!$R$990 -> 21294.66 | L6: 21385.78 | M6: 18005 | N6: ='Revnue - NSO Supplies 2021'!$U$990 -> 187443.27 | P6: ='Revnue - NSO Supplies 2021'!$W$990 -> 281656 | Q6: ='Revnue - NSO Supplies 2021'!$X$990 -> 437656 | R6: ='Revnue - NSO Supplies 2021'!$Y$990 -> 15620.272 | S6: =P6/12 -> 23471.333
A7: Equipment | B7: ='Revenue - Equipment 2022'!$I$28 -> 2079.41 | C7: ='Revenue - Equipment 2022'!$J$28 -> 5678.35 | D7: ='Revenue - Equipment 2022'!$K$28 -> 0 | E7: ='Revenue - Equipment 2022'!$L$28 -> 0 | F7: ='Revenue - Equipment 2022'!$M$28 -> 0 | G7: ='Revenue - Equipment 2022'!$N$28 -> 795 | H7: ='Revenue - Equipment 2022'!$O$28 -> 5239.23 | I7: ='Revenue - Equipment 2022'!$P$28 -> 2845.74 | J7: ='Revenue - Equipment 2022'!$Q$28 -> 325 | K7: ='Revenue - Equipment 2022'!$R$28 -> 2885 | L7: ='Revenue - Equipment 2022'!$S$28 -> 0 | M7: ='Revenue - Equipment 2022'!$T$28 -> 10465 | N7: ='Revenue - Equipment 2022'!$U$28 -> 30312.73 | P7: ='Revenue - Equipment 2022'!$W$28 -> 23153 | Q7: ='Revenue - Equipment 2022'!$X$28 -> 33153 | R7: ='Revenue - Equipment 2022'!$Y$28 -> 2526.0608 | S7: =P7/12 -> 1929.4167
A8: Service | B8: ='Revnue - Service 2022'!$I$15 -> 0 | C8: ='Revnue - Service 2022'!$J$15 -> 270 | D8: ='Revnue - Service 2022'!$K$15 -> 0 | E8: ='Revnue - Service 2022'!$L$15 -> 0 | F8: ='Revnue - Service 2022'!$M$15 -> 0 | G8: ='Revnue - Service 2022'!$N$15 -> 0 | H8: ='Revnue - Service 2022'!$O$15 -> 810 | I8: ='Revnue - Service 2022'!$P$15 -> 975 | J8: ='Revnue - Service 2022'!$Q$15 -> 1530 | K8: ='Revnue - Service 2022'!$R$15 -> 720 | L8: 0 | M8: 0 | N8: ='Revnue - Service 2022'!$U$15 -> 4305 | P8: ='Revnue - Service 2022'!$W$15 -> 900 | Q8: ='Revnue - Service 2022'!$X$15 -> 1500 | R8: ='Revnue - Service 2022'!$Y$15 -> 358.75 | S8: =P8/12 -> 75
A10: ='Revnue - Spot On Supplies 2022'!$A$34 -> *** RUNNING TOTAL *** | B10: =SUM(B4:B8) -> 5532.1 | C10: =SUM(C4:C8) -> 17758.47 | D10: =SUM(D4:D8) -> 26358.35 | E10: =SUM(E4:E8) -> 32411.595 | F10: =SUM(F4:F8) -> 16321.93 | G10: =SUM(G4:G8) -> 25294.93 | H10: =SUM(H4:H8) -> 26339.77 | I10: =SUM(I4:I8) -> 22011.47 | ... N10: =SUM(N4:N8) -> 227836.42 | P10: =SUM(P4:P8) -> 450760 | Q10: =SUM(Q4:Q8) -> 749860 | R10: =N10/12 -> 18986.368 | S10: =SUM(S4:S8) -> 37563.333
A13: Account Category | B13: Jan | C13: Feb | D13: Mar | E13: Apr | F13: May | G13: Jun | H13: Jul | I13: Aug | J13: Sep | K13: Oct | L13: Nov | M13: Dec | N13: TOTAL | P13: Budget | Q13: Goal | R13: AVG/MONTH | S13: BUDGET AVG/MONTH
A14: 2022 Year
A16: SOS | B16: ='Revnue - Spot On Supplies 2022'!$I$98 -> 888.59 | C16: ='Revnue - Spot On Supplies 2022'!$J$98 -> 1979.66 | D16: ='Revnue - Spot On Supplies 2022'!$K$98 -> 3682.17 | E16: ='Revnue - Spot On Supplies 2022'!$L$98 -> 1848.64 | F16: ='Revnue - Spot On Supplies 2022'!$M$98 -> 1684.79 | G16: ='Revnue - Spot On Supplies 2022'!$N$98 -> 3303.3 | H16: ='Revnue - Spot On Supplies 2022'!$O$98 -> 662.82 | I16: ='Revnue - Spot On Supplies 2022'!$P$98 -> 1829.6 | J16: ='Revnue - Spot On Supplies 2022'!$Q$98 -> 1791.53 | K16: ='Revnue - Spot On Supplies 2022'!$R$98 -> 983.6 | L16: ='Revnue - Spot On Supplies 2022'!$S$98 -> 2287.7 | M16: ='Revnue - Spot On Supplies 2022'!$T$98 -> 326.54 | N16: ='Revnue - Spot On Supplies 2022'!$U$98 -> 21017.48 | P16: ='Revnue - Spot On Supplies 2022'!$W$98 -> 19266.023 | Q16: ='Revnue - Spot On Supplies 2022'!$X$98 -> 24520.393 | R16: ='Revnue - Spot On Supplies 2022'!$Y$98 -> 1751.4567 | S16: =P16/12 -> 1605.5019
A17: SOE | B17: ='SO Equipment 2022'!$I$29 -> 0 | C17: ='SO Equipment 2022'!$J$29 -> 0 | D17: ='SO Equipment 2022'!$K$29 -> 0 | E17: ='SO Equipment 2022'!$L$29 -> 0 | F17: ='SO Equipment 2022'!$M$29 -> 0 | G17: ='SO Equipment 2022'!$N$29 -> 0 | H17: ='SO Equipment 2022'!$O$29 -> 0 | I17: ='SO Equipment 2022'!$P$29 -> 0 | J17: ='SO Equipment 2022'!$Q$29 -> 0 | K17: ='SO Equipment 2022'!$R$29 -> 200 | L17: ='SO Equipment 2022'!$S$29 -> 0 | M17: ='SO Equipment 2022'!$T$29 -> 0 | N17: ='SO Equipment 2022'!$U$29 -> 200 | P17: ='SO Equipment 2022'!$W$29 -> 149964 | Q17: ='SO Equipment 2022'!$X$29 -> 294964 | R17: ='SO Equipment 2022'!$Y$29 -> 16.666667 | S17: =P17/12 -> 12497
A18: NSO Supplies | B18: ='Revnue - NAHSO Supplies_2022'!$I$328 -> 15187.25 | C18: ='Revnue - NAHSO Supplies_2022'!$J$328 -> 15998 | D18: ='Revnue - NAHSO Supplies_2022'!$K$328 -> 15424.5 | E18: ='Revnue - NAHSO Supplies_2022'!$L$328 -> 23055 | F18: ='Revnue - NAHSO Supplies_2022'!$M$328 -> 11812.38 | G18: ='Revnue - NAHSO Supplies_2022'!$N$328 -> 17417 | H18: ='Revnue - NAHSO Supplies_2022'!$O$328 -> 26475.84 | I18: ='Revnue - NAHSO Supplies_2022'!$P$328 -> 24642 | J18: ='Revnue - NAHSO Supplies_2022'!$Q$328 -> 20533 | K18: ='Revnue - NAHSO Supplies_2022'!$R$328 -> 16663.5 | L18: ='Revnue - NAHSO Supplies_2022'!$S$328 -> 26155 | M18: ='Revnue - NAHSO Supplies_2022'!$T$328 -> 12002 | N18: ='Revnue - NAHSO Supplies_2022'!$U$328 -> 225365.47 | P18: ='Revnue - NAHSO Supplies_2022'!$W$328 -> 206585.01 | Q18: ='Revnue - NAHSO Supplies_2022'!$X$328 -> 262926.38 | R18: ='Revnue - NAHSO Supplies_2022'!$Y$328 -> 18780.456 | S18: =P18/12 -> 17215.418
A19: Equipment | B19: ='Revenue - Equipment 2022'!$I$82 -> 1191 | C19: ='Revenue - Equipment 2022'!$J$82 -> 11902 | D19: ='Revenue - Equipment 2022'!$K$82 -> 3100 | E19: ='Revenue - Equipment 2022'!$L$82 -> 4511 | F19: ='Revenue - Equipment 2022'!$M$82 -> 99 | G19: ='Revenue - Equipment 2022'!$N$82 -> 2584 | H19: ='Revenue - Equipment 2022'!$O$82 -> 1189 | I19: ='Revenue - Equipment 2022'!$P$82 -> 5709 | J19: ='Revenue - Equipment 2022'!$Q$82 -> 3895 | K19: ='Revenue - Equipment 2022'!$R$82 -> 11727.16 | L19: ='Revenue - Equipment 2022'!$S$82 -> 4797 | M19: ='Revenue - Equipment 2022'!$T$82 -> 7404 | N19: ='Revenue - Equipment 2022'!$U$82 -> 58108.16 | P19: ='Revenue - Equipment 2022'!$W$82 -> 83386 | Q19: ='Revenue - Equipment 2022'!$X$82 -> 108096 | R19: ='Revenue - Equipment 2022'!$Y$82 -> 7952.5742 | S19: =P19/12 -> 6948.8333
A20: Service | B20: ='Revnue - Service 2022'!$I$78 -> 4250 | C20: ='Revnue - Service 2022'!$J$78 -> 810 | D20: ='Revnue - Service 2022'!$K$78 -> 900 | E20: ='Revnue - Service 2022'!$L$78 -> 810 | F20: ='Revnue - Service 2022'!$M$78 -> 480 | G20: ='Revnue - Service 2022'!$N$78 -> 3600 | H20: ='Revnue - Service 2022'!$O$78 -> 945 | I20: ='Revnue - Service 2022'!$P$78 -> 1495 | J20: ='Revnue - Service 2022'!$Q$78 -> 415 | K20: ='Revnue - Service 2022'!$R$78 -> 2013 | L20: ='Revnue - Service 2022'!$S$78 -> 1620 | M20: ='Revnue - Service 2022'!$T$78 -> 1160 | N20: ='Revnue - Service 2022'!$U$78 -> 18498 | P20: ='Revnue - Service 2022'!$W$78 -> 17856.5 | Q20: ='Revnue - Service 2022'!$X$78 -> 23081 | R20: ='Revnue - Service 2022'!$Y$78 -> 1900.25 | S20: =P20/12 -> 1488.0417
A22: *** RUNNING TOTAL *** | B22: =SUM(B16:B20) -> 21516.84 | C22: =SUM(C16:C20) -> 30689.66 | D22: =SUM(D16:D20) -> 23106.67 | E22: =SUM(E16:E20) -> 30224.64 | F22: =SUM(F16:F20) -> 14076.17 | G22: =SUM(G16:G20) -> 26904.3 | H22: =SUM(H16:H20) -> 29272.66 | I22: =SUM(I16:I20) -> 33675.6 | ... N22: =SUM(N16:N20) -> 323189.11 | P22: 441958 | Q22: 735858 | R22: 18174.138 | S22: 36829.833
A25: =Totals!$A$13 -> Account Category | B25: =Totals!$B$13 -> Jan | C25: =Totals!$C$13 -> Feb | D25: =Totals!$D$13 -> Mar | E25: =Totals!$E$13 -> Apr | F25: =Totals!$F$13 -> May | G25: =Totals!$G$13 -> Jun | H25: =Totals!$H$13 -> Jul | I25: =Totals!$I$13 -> Aug | J25: =Totals!$J$13 -> Sep | K25: =Totals!$K$13 -> Oct | L25: =Totals!$L$13 -> Nov | M25: =Totals!$M$13 -> Dec | N25: =Totals!$N$13 -> TOTAL | P25: =Totals!$P$13 -> Budget | Q25: =Totals!$Q$13 -> Goal | R25: =Totals!$R$13 -> AVG/MONTH | S25: =Totals!$S$13 -> BUDGET AVG/MONTH
A26: =Sheet15!$A$3 -> 2023 Year
A28: =Totals!$A$16 -> SOS | B28: ='Revnue - Spot On Supplies 2022'!$I$116 -> 0 | C28: ='Revnue - Spot On Supplies 2022'!$J$116 -> 0 | D28: ='Revnue - Spot On Supplies 2022'!$K$116 -> 0 | E28: ='Revnue - Spot On Supplies 2022'!$L$116 -> 0 | F28: ='Revnue - Spot On Supplies 2022'!$M$116 -> 0 | G28: ='Revnue - Spot On Supplies 2022'!$N$116 -> 0 | H28: ='Revnue - Spot On Supplies 2022'!$O$116 -> 0 | I28: ='Revnue - Spot On Supplies 2022'!$P$116 -> 0 | J28: ='Revnue - Spot On Supplies 2022'!$Q$116 -> 0 | K28: ='Revnue - Spot On Supplies 2022'!$R$116 -> 0 | L28: ='Revnue - Spot On Supplies 2022'!$S$116 -> 0 | M28: ='Revnue - Spot On Supplies 2022'!$T$116 -> 0 | N28: ='Revnue - Spot On Supplies 2022'!$U$116 -> 0 | P28: ='Revnue - Spot On Supplies 2022'!$W$116 -> 40203.412 | Q28: ='Revnue - Spot On Supplies 2022'!$X$116 -> 54854.525 | R28: ='Revnue - Spot On Supplies 2022'!$Y$116 -> 2217.0375 | S28: =Totals!$S$16 -> 1605.5019
A29: =Totals!$A$17 -> SOE | B29: ='SO Equipment 2022'!$I$46 -> 0 | C29: ='SO Equipment 2022'!$J$46 -> 0 | D29: ='SO Equipment 2022'!$K$46 -> 0 | E29: ='SO Equipment 2022'!$L$46 -> 0 | F29: ='SO Equipment 2022'!$M$46 -> 0 | G29: ='SO Equipment 2022'!$N$46 -> 0 | H29: ='SO Equipment 2022'!$O$46 -> 0 | I29: ='SO Equipment 2022'!$P$46 -> 0 | J29: ='SO Equipment 2022'!$Q$46 -> 0 | K29: ='SO Equipment 2022'!$R$46 -> 0 | L29: ='SO Equipment 2022'!$S$46 -> 0 | M29: ='SO Equipment 2022'!$T$46 -> 0 | N29: ='SO Equipment 2022'!$U$46 -> 0 | P29: ='SO Equipment 2022'!$W$46 -> 992 | Q29: ='SO Equipment 2022'!$X$46 -> 1492 | R29: ='SO Equipment 2022'!$Y$46 -> 0 | S29: =Totals!$S$17 -> 12497
A30: =Totals!$A$18 -> NSO Supplies | B30: ='Revnue - NAHSO Supplies_2022'!$I$1234 -> 14604.5 | C30: ='Revnue - NAHSO Supplies_2022'!$J$1234 -> 15994 | D30: ='Revnue - NAHSO Supplies_2022'!$K$1234 -> 18183.69 | E30: ='Revnue - NAHSO Supplies_2022'!$L$1234 -> 20411.54 | F30: ='Revnue - NAHSO Supplies_2022'!$M$1234 -> 30794.14 | G30: ='Revnue - NAHSO Supplies_2022'!$N$1234 -> 19291.02 | H30: ='Revnue - NAHSO Supplies_2022'!$O$1234 -> 0 | I30: ='Revnue - NAHSO Supplies_2022'!$P$1234 -> 19095 | J30: ='Revnue - NAHSO Supplies_2022'!$Q$1234 -> 0 | K30: ='Revnue - NAHSO Supplies_2022'!$R$1234 -> 0 | L30: ='Revnue - NAHSO Supplies_2022'!$S$1234 -> 0 | M30: ='Revnue - NAHSO Supplies_2022'!$T$1234 -> 0 | N30: ='Revnue - NAHSO Supplies_2022'!$U$1234 -> 138373.89 | P30: ='Revnue - NAHSO Supplies_2022'!$W$1044 -> 0 | Q30: ='Revnue - NAHSO Supplies_2022'!$X$1044 -> 0 | R30: ='Revnue - NAHSO Supplies_2022'!$Y$1044 -> 0 | S30: =Totals!$S$18 -> 17215.418
A31: =Totals!$A$19 -> Equipment | B31: ='Revenue - Equipment 2022'!$I$239 -> 5274 | C31: ='Revenue - Equipment 2022'!$J$239 -> 6262 | D31: ='Revenue - Equipment 2022'!$K$239 -> 13184.37 | E31: ='Revenue - Equipment 2022'!$L$239 -> 1569 | F31: ='Revenue - Equipment 2022'!$M$239 -> 5876.79 | G31: ='Revenue - Equipment 2022'!$N$239 -> 99 | H31: ='Revenue - Equipment 2022'!$O$239 -> 12448.63 | I31: ='Revenue - Equipment 2022'!$P$239 -> 99 | J31: ='Revenue - Equipment 2022'!$Q$239 -> 99 | K31: ='Revenue - Equipment 2022'!$R$239 -> 99 | L31: ='Revenue - Equipment 2022'!$S$239 -> 3832.51 | M31: ='Revenue - Equipment 2022'!$T$239 -> 12448.63 | N31: ='Revenue - Equipment 2022'!$U$239 -> 35790.77 | P31: ='Revenue - Equipment 2022'!$W$239 -> 113013 | Q31: ='Revenue - Equipment 2022'!$X$239 -> 133613 | R31: ='Revenue - Equipment 2022'!$Y$239 -> 218.12083 | S31: =Totals!$S$19 -> 6948.8333
A32: =Totals!$A$20 -> Service | B32: ='Revnue - Service 2022'!$I$96 -> 1350 | C32: ='Revnue - Service 2022'!$J$96 -> 720 | D32: ='Revnue - Service 2022'!$K$96 -> 2733 | E32: ='Revnue - Service 2022'!$L$96 -> 720 | F32: ='Revnue - Service 2022'!$M$96 -> 0 | G32: ='Revnue - Service 2022'!$N$96 -> 0 | H32: ='Revnue - Service 2022'!$O$96 -> 0 | I32: ='Revnue - Service 2022'!$P$96 -> 0 | J32: ='Revnue - Service 2022'!$Q$96 -> 0 | K32: ='Revnue - Service 2022'!$R$96 -> 0 | L32: ='Revnue - Service 2022'!$S$96 -> 0 | M32: ='Revnue - Service 2022'!$T$96 -> 0 | N32: ='Revnue - Service 2022'!$U$96 -> 4153 | P32: ='Revnue - Service 2022'!$W$96 -> 29085.25 | Q32: ='Revnue - Service 2022'!$X$96 -> 5322.1667 | R32: ='Revnue - Service 2022'!$Y$96 -> 2879.5 | S32: =Totals!$S$20 -> 1488.0417
A34: *** RUNNING TOTAL *** | B34: =SUM(B28:B32) -> 21228.5 | C34: =SUM(C28:C32) -> 22976 | D34: =SUM(D28:D32) -> 34101.06 | E34: =SUM(E28:E32) -> 22700.54 | F34: =SUM(F28:F32) -> 36670.93 | G34: =SUM(G28:G32) -> 19390.02 | H34: =SUM(H28:H32) -> 12448.63 | I34: =SUM(I28:I32) -> 19194 | ... N34: =SUM(N28:N32) -> 178317.66 | P34: 441958 | Q34: 735858 | R34: 18174.138 | S34: 36829.833
A37: =Totals!$A$13 -> Account Category | B37: =Totals!$B$13 -> Jan | C37: =Totals!$C$13 -> Feb | D37: =Totals!$D$13 -> Mar | E37: =Totals!$E$13 -> Apr | F37: =Totals!$F$13 -> May | G37: =Totals!$G$13 -> Jun | H37: =Totals!$H$13 -> Jul | I37: =Totals!$I$13 -> Aug | J37: =Totals!$J$13 -> Sep | K37: =Totals!$K$13 -> Oct | L37: =Totals!$L$13 -> Nov | M37: =Totals!$M$13 -> Dec | N37: =Totals!$N$13 -> TOTAL | P37: =Totals!$P$13 -> Budget | Q37: =Totals!$Q$13 -> Goal | R37: =Totals!$R$13 -> AVG/MONTH | S37: =Totals!$S$13 -> BUDGET AVG/MONTH
A38: =Sheet15!$A$4 -> 2024 Year
A40: =Totals!$A$28 -> SOS | B40: =Totals!$B$28 -> 0 | C40: =Totals!$C$28 -> 0 | D40: =Totals!$D$28 -> 0 | E40: =Totals!$E$28 -> 0 | F40: =Totals!$F$28 -> 0 | G40: =Totals!$G$28 -> 0 | H40: =Totals!$H$28 -> 0 | I40: =Totals!$I$28 -> 0 | J40: =Totals!$J$28 -> 0 | K40: =Totals!$K$28 -> 0 | L40: =Totals!$L$28 -> 0 | M40: =Totals!$M$28 -> 0 | N40: =Totals!$N$28 -> 0 | P40: =Totals!$P$28 -> 40203.412 | Q40: =Totals!$Q$28 -> 54854.525 | R40: =Totals!$R$28 -> 2217.0375 | S40: =Totals!$S$28 -> 1605.5019
A41: =Totals!$A$29 -> SOE | B41: =Totals!$B$29 -> 0 | C41: =Totals!$C$29 -> 0 | D41: =Totals!$D$29 -> 0 | E41: =Totals!$E$29 -> 0 | F41: =Totals!$F$29 -> 0 | G41: =Totals!$G$29 -> 0 | H41: =Totals!$H$29 -> 0 | I41: =Totals!$I$29 -> 0 | J41: =Totals!$J$29 -> 0 | K41: =Totals!$K$29 -> 0 | L41: =Totals!$L$29 -> 0 | M41: =Totals!$M$29 -> 0 | N41: =Totals!$N$29 -> 0 | P41: =Totals!$P$29 -> 992 | Q41: =Totals!$Q$29 -> 1492 | R41: =Totals!$R$29 -> 0 | S41: =Totals!$S$29 -> 12497
A42: =Totals!$A$30 -> NSO Supplies | B42: =Totals!$B$30 -> 14604.5 | C42: =Totals!$C$30 -> 15994 | D42: =Totals!$D$30 -> 18183.69 | E42: =Totals!$E$30 -> 20411.54 | F42: =Totals!$F$30 -> 30794.14 | G42: =Totals!$G$30 -> 19291.02 | H42: =Totals!$H$30 -> 0 | I42: =Totals!$I$30 -> 19095 | J42: =Totals!$J$30 -> 0 | K42: =Totals!$K$30 -> 0 | L42: =Totals!$L$30 -> 0 | M42: =Totals!$M$30 -> 0 | N42: =Totals!$N$30 -> 138373.89 | P42: =Totals!$P$30 -> 0 | Q42: =Totals!$Q$30 -> 0 | R42: =Totals!$R$30 -> 0 | S42: =Totals!$S$30 -> 17215.418
A43: =Totals!$A$31 -> Equipment | B43: =Totals!$B$31 -> 5274 | C43: =Totals!$C$31 -> 6262 | D43: =Totals!$D$31 -> 13184.37 | E43: =Totals!$E$31 -> 1569 | F43: =Totals!$F$31 -> 5876.79 | G43: =Totals!$G$31 -> 99 | H43: =Totals!$H$31 -> 12448.63 | I43: =Totals!$I$31 -> 99 | J43: =Totals!$J$31 -> 99 | K43: =Totals!$K$31 -> 99 | L43: =Totals!$L$31 -> 3832.51 | M43: =Totals!$M$31 -> 12448.63 | N43: =Totals!$N$31 -> 35790.77 | P43: =Totals!$P$31 -> 113013 | Q43: =Totals!$Q$31 -> 133613 | R43: =Totals!$R$31 -> 218.12083 | S43: =Totals!$S$31 -> 6948.8333
A44: =Totals!$A$32 -> Service | B44: =Totals!$B$32 -> 1350 | C44: =Totals!$C$32 -> 720 | D44: =Totals!$D$32 -> 2733 | E44: =Totals!$E$32 -> 720 | F44: =Totals!$F$32 -> 0 | G44: =Totals!$G$32 -> 0 | H44: =Totals!$H$32 -> 0 | I44: =Totals!$I$32 -> 0 | J44: =Totals!$J$32 -> 0 | K44: =Totals!$K$32 -> 0 | L44: =Totals!$L$32 -> 0 | M44: =Totals!$M$32 -> 0 | N44: =Totals!$N$32 -> 4153 | P44: =Totals!$P$32 -> 29085.25 | Q44: =Totals!$Q$32 -> 5322.1667 | R44: =Totals!$R$32 -> 2879.5 | S44: =Totals!$S$32 -> 1488.0417
A46: =Totals!$A$34 -> *** RUNNING TOTAL *** | B46: =Totals!$B$34 -> 21228.5 | C46: =Totals!$C$34 -> 22976 | D46: =Totals!$D$34 -> 34101.06 | E46: =Totals!$E$34 -> 22700.54 | F46: =Totals!$F$34 -> 36670.93 | G46: =Totals!$G$34 -> 19390.02 | H46: =Totals!$H$34 -> 12448.63 | I46: =Totals!$I$34 -> 19194 | J46: =Totals!$J$34 -> 99 | K46: =Totals!$K$34 -> 99 | L46: =Totals!$L$34 -> 3832.51 | M46: =Totals!$M$34 -> 12448.63 | N46: =Totals!$N$34 -> 178317.66 | P46: =Totals!$P$34 -> 441958 | Q46: =Totals!$Q$34 -> 735858 | R46: =Totals!$R$34 -> 18174.138 | S46: =Totals!$S$34 -> 36829.833
S124: ='Revnue - Spot On Supplies 2022'!$Y$98 -> 1751.4567

Sheet SO Equipment 2022
A1: Account Name | B1: A/E | C1: CONTACT | D1: Subscription | E1: NOTES / STATUS | F1: Close Date | G1: Amount | H1: Status | I1: Jan | J1: Feb | K1: Mar | L1: Apr | M1: May | N1: Jun | O1: Jul | P1: Aug | Q1: Sep | R1: Oct | S1: Nov | T1: Dec | U1: TOTAL | W1: Budget | X1: Goal | Y1: AVG/MONTH
A2: *** ONBOARD ***
A4: Ruiz Auto | B4: AH | U4: =SUM(I4:T4) -> 0 | W4: 10000 | X4: 20000 | Y4: =U4/12 -> 0
U5: =SUM(I5:T5) -> 0 | W5: 10000 | X5: 20000 | Y5: =U5/12 -> 0
U6: =SUM(I6:T6) -> 0 | W6: 10000 | X6: 20000 | Y6: =U6/12 -> 0
U7: =SUM(I7:T7) -> 0 | W7: 10000 | X7: 20000 | Y7: =U7/12 -> 0
U8: =SUM(I8:T8) -> 0 | W8: 10000 | X8: 20000 | Y8: =U8/12 -> 0
U9: =SUM(I9:T9) -> 0 | W9: 10000 | X9: 20000 | Y9: =U9/12 -> 0
U10: =SUM(I10:T10) -> 0 | W10: 10000 | X10: 20000 | Y10: =U10/12 -> 0
U11: =SUM(I11:T11) -> 0 | W11: 10000 | X11: 20000 | Y11: =U11/12 -> 0
U12: =SUM(I12:T12) -> 0 | W12: 10000 | X12: 20000 | Y12: =U12/12 -> 0
U13: =SUM(I13:T13) -> 0 | W13: 10000 | X13: 20000 | Y13: =U13/12 -> 0
U14: =SUM(I14:T14) -> 0 | W14: 10000 | X14: 20000 | Y14: =U14/12 -> 0
U15: =SUM(I15:T15) -> 0 | W15: 10000 | X15: 20000 | Y15: =U15/12 -> 0
Y16: =U16/12 -> 0
A17: *** RUNNING TOTAL *** | I17: =SUM(I2:I16) -> 0 | J17: =SUM(J2:J16) -> 0 | K17: =SUM(K2:K16) -> 0 | L17: =SUM(L2:L16) -> 0 | M17: =SUM(M2:M16) -> 0 | N17: =SUM(N2:N16) -> 0 | O17: =SUM(O2:O16) -> 0 | P17: =SUM(P2:P16) -> 0 | ... X17: =SUM(X2:X16) -> 240000 | Y17: =U17/12 -> 0
A18: Bruno's Deli, Market, Café | E18: Spoke to Steve 415-785-7487
A19: Fire Island Grill - Palmdale | D19: Toast | E19: Patrick @661-802-6071 pburke@fireislandgrill.com | U19: =SUM(I19:T19) -> 0 | W19: 992 | X19: 1492 | Y19: =U19/12 -> 0
A20: Fire Island Grill - Simi Valley | U20: =SUM(I20:T20) -> 0 | W20: 993 | X20: 1493 | Y20: =U20/12 -> 0
A21: Stony Point Market | R21: 200 | U21: =SUM(I21:T21) -> 200 | W21: 994 | X21: 1494 | Y21: =U21/12 -> 16.666667
U22: =SUM(I22:T22) -> 0 | W22: 995 | X22: 1495 | Y22: =U22/12 -> 0
U23: =SUM(I23:T23) -> 0 | W23: 996 | X23: 1496 | Y23: =U23/12 -> 0
U24: =SUM(I24:T24) -> 0 | W24: 997 | X24: 1497 | Y24: =U24/12 -> 0
U25: =SUM(I25:T25) -> 0 | W25: 998 | X25: 1498 | Y25: =U25/12 -> 0
U26: =SUM(I26:T26) -> 0 | W26: 999 | X26: 1499 | Y26: =U26/12 -> 0
U27: =SUM(I27:T27) -> 0 | W27: 1000 | X27: 1500 | Y27: =U27/12 -> 0
U28: =SUM(I28:T28) -> 0 | W28: 1000 | X28: 1500 | Y28: =U28/12 -> 0
I29: =SUM( I14:I28) -> 0 | J29: =SUM( J14:J28) -> 0 | K29: =SUM( K14:K28) -> 0 | L29: =SUM( L14:L28) -> 0 | M29: =SUM( M14:M28) -> 0 | N29: =SUM( N14:N28) -> 0 | O29: =SUM( O14:O28) -> 0 | P29: =SUM( P14:P28) -> 0 | ... Y29: =SUM( Y14:Y28) -> 16.666667
I31: 0 | J31: 0 | K31: 0 | L31: 0 | M31: 0 | N31: 0 | O31: 0 | P31: 0 | Q31: 0 | R31: 0 | S31: 0 | T31: 0 | U31: =SUM(I31:T31) -> 0 | W31: 992 | X31: 1492 | Y31: =U31/12 -> 0
A46: *** RUNNING TOTAL *** | I46: =SUM( I31:I45) -> 0 | J46: =SUM( J31:J45) -> 0 | K46: =SUM( K31:K45) -> 0 | L46: =SUM( L31:L45) -> 0 | M46: =SUM( M31:M45) -> 0 | N46: =SUM( N31:N45) -> 0 | O46: =SUM( O31:O45) -> 0 | P46: =SUM( P31:P45) -> 0 | ... U46: =SUM( U31:U45) -> 0 | W46: =SUM( W31:W45) -> 992 | X46: =SUM( X31:X45) -> 1492 | Y46: =SUM( Y31:Y45) -> 0

Sheet Revnue - Spot On Supplies 2022
A1: Account Name | B1: A/E | C1: Primary tech | D1: INSTALL STATUS | E1: NOTES | F1: Close Date | G1: Amount | H1: Status | I1: Jan | J1: Feb | K1: Mar | L1: Apr | M1: May | N1: Jun | O1: Jul | P1: Aug | Q1: Sep | R1: Oct | S1: Nov | T1: Dec | U1: TOTAL | W1: Budget | X1: Goal | Y1: AVG/MONTH
A2: *** ONBOARD ***
A4: La Costanera | B4: Stephen | C4: Jeremy | D4: LIVE 6/21 | M4: 291.65 | O4: 329.84 | P4: 74.88 | Q4: 345.31 | U4: =SUM(I4:T4) -> 1041.68 | W4: 1000 | X4: 1500 | Y4: =U4/12 -> 86.806667
A5: The Forge Handcrafted Pizza | B5: Dave | C5: Jeremy | D5: LIVE 6/21 | N5: 170.25 | O5: 131.2 | Q5: 339.21 | U5: =SUM(I5:T5) -> 640.66 | W5: 1000 | X5: 1500 | Y5: =U5/12 -> 53.388333
A6: BARREL HOUSE TAVERN | Q6: 543.75 | U6: =SUM(I6:T6) -> 543.75 | Y6: =U6/12 -> 45.3125
A7: Cote Ouest | B7: Suzie | C7: Jeremy | D7: Live 3/21 | K7: 151.51 | N7: 108.5 | Q7: 57.88 | U7: =SUM(I7:T7) -> 317.89 | W7: 1000 | X7: 1500 | Y7: =U7/12 -> 26.490833
A8: Troy Greek Cuisine- Martinez | B8: Cory | C8: Nima | D8: LIVE 7/21 | O8: 165.43 | R8: 138.73 | U8: =SUM(I8:T8) -> 304.16 | W8: 1000 | X8: 1500 | Y8: =U8/12 -> 25.346667
A9: Papalote- 2 loc | B9: Dave | C9: Rick | D9: LIVE 4/21 | L9: 86 | M9: 213 | U9: =SUM(I9:T9) -> 299 | W9: 1000 | X9: 1500 | Y9: =U9/12 -> 24.916667
A10: Bacco- Sf | B10: Bill | C10: Rick | D10: LIVE 1/21 | J10: 78.93 | M10: 70.93 | Q10: 129 | U10: =SUM(I10:T10) -> 278.86 | W10: 1000 | X10: 1500 | Y10: =U10/12 -> 23.238333
A11: Via Piccola | B11: Jeremy | C11: Jeremy | D11: Pedro | E11: Suzie C | O11: 212.76 | U11: =SUM(I11:T11) -> 212.76 | W11: 1000 | X11: 1500 | Y11: =U11/12 -> 17.73
A12: PRIMAVERA RESTAURANT | R12: 211.35 | U12: =SUM(I12:T12) -> 211.35 | W12: 1004 | X12: 1504 | Y12: =U12/12 -> 17.6125
A13: Isabel’s Vintage Cafe | P13: 202.95 | U13: =SUM(I13:T13) -> 202.95 | W13: 1000 | X13: 1500 | Y13: =U13/12 -> 16.9125
A14: Gilroy Garlic Festival | B14: James H | C14: Terry | D14: Live 7/21 | O14: 175.69 | U14: =SUM(I14:T14) -> 175.69 | W14: 1000 | X14: 1500 | Y14: =U14/12 -> 14.640833
A15: The Caviar Company | E15: FLUP 7/28 Petra 806-777-5864 | K15: 151.51 | U15: =SUM(I15:T15) -> 151.51 | W15: 1000 | X15: 1500 | Y15: =U15/12 -> 12.625833
A16: El Huarache Loco | B16: Suzie | C16: Milton | D16: Live | L16: 140.61 | S16: 251.46 | U16: =SUM(I16:T16) -> 392.07 | W16: 1000 | X16: 1500 | Y16: =U16/12 -> 32.6725
A17: Bolinas People's Store ( NCC) | B17: Rich | C17: Lowell | D17: Live 5/21 | M17: 123 | U17: =SUM(I17:T17) -> 123 | W17: 1000 | X17: 1500 | Y17: =U17/12 -> 10.25
A18: KITCHEN + KOCKTAILS CHICAGO | R18: 116.59 | U18: =SUM(I18:T18) -> 116.59 | W18: 1005 | X18: 1505 | Y18: =U18/12 -> 9.7158333
A19: VIA PICCOLA TRATTORIA | Q19: 114.43 | U19: =SUM(I19:T19) -> 114.43 | W19: 1001 | X19: 1501 | Y19: =U19/12 -> 9.5358333
A20: Buffalo Billiards | B20: Milton | C20: Milton | D20: Live 7/26 | E20: Mike bombace@buffalo-billiards.com has pricing on supplies Buffalo Billiards Lee Simon +17075858992 246 Petaluma Blvd N Petaluma, CA 94952 | O20: 103.29 | U20: =SUM(I20:T20) -> 103.29 | W20: 1000 | X20: 1500 | Y20: =U20/12 -> 8.6075
A21: PRIMAVERA RESTAURANT | R21: 93.83 | U21: =SUM(I21:T21) -> 93.83 | W21: 1011 | X21: 1511 | Y21: =U21/12 -> 7.8191667
A22: PRIMAVERA RESTAURANT | R22: 68.81 | U22: =SUM(I22:T22) -> 68.81 | W22: 1009 | X22: 1509 | Y22: =U22/12 -> 5.7341667
A23: Troy Greek Express | B23: Cory | C23: Nima | D23: LIVE 7/21 | R23: 68.61 | U23: =SUM(I23:T23) -> 68.61 | W23: 1000 | X23: 1500 | Y23: 25.346667
A24: SARA'S SOUTHERN KITCHEN | R24: 50.61 | U24: =SUM(I24:T24) -> 50.61 | W24: 1007 | X24: 1507 | Y24: =U24/12 -> 4.2175
A25: SARA WILLIAMS | R25: 50.27 | U25: =SUM(I25:T25) -> 50.27 | W25: 1008 | X25: 1508 | Y25: =U25/12 -> 4.1891667
A26: BEYOND THE GLORY | B26: AH | P26: 47.33 | U26: =SUM(I26:T26) -> 47.33 | Y26: =U26/12 -> 3.9441667
A27: DAVRE CLUB | R27: 47.02 | U27: =SUM(I27:T27) -> 47.02 | W27: 1006 | X27: 1506 | Y27: =U27/12 -> 3.9183333
A28: Sausage Emporium | B28: Jeremy | C28: Jeremy | D28: LIVE 7/21 | O28: 42.61 | U28: =SUM(I28:T28) -> 42.61 | W28: 1000 | X28: 1500 | Y28: =U28/12 -> 3.5508333
A29: La Meza Mediteranean | B29: Corp | C29: Nikaela | D29: Live 2020 | N29: 42.51 | U29: =SUM(I29:T29) -> 42.51 | W29: 1000 | X29: 1500 | Y29: =U29/12 -> 3.5425
A30: Kell's Irish | B30: Jose | C30: Rick | D30: Live 4/21 | L30: 34.18 | U30: =SUM(I30:T30) -> 34.18 | W30: 1000 | X30: 1500 | Y30: =U30/12 -> 2.8483333
Y33: =U33/12 -> 0
A34: *** RUNNING TOTAL *** | I34: =SUM(I2:I33) -> 0 | J34: =SUM(J2:J33) -> 78.93 | K34: =SUM(K2:K33) -> 303.02 | L34: =SUM(L2:L33) -> 260.79 | M34: =SUM(M2:M33) -> 698.58 | N34: =SUM(N2:N33) -> 321.26 | O34: =SUM(O2:O33) -> 1160.82 | P34: =SUM(P2:P33) -> 325.16 | ... X34: =SUM(X2:X33) -> 37551 | Y34: =U34/12 -> 481.285
A36: BARREL HOUSE TAVERN | I36: 338.63 | K36: 598.13 | N36: 1051 | Q36: 1170 | U36: =SUM(I36:T36) -> 3157.76 | W36: {=MMULT(Y36,11)} -> 2894.6133 | X36: =MMULT(Y36,14) -> 3684.0533 | Y36: =U36/12 -> 263.14667
A37: THE FORGE HANDCRAFTED | J37: 221.22 | K37: 269.04 | M37: 215.22 | N37: 313.5 | P37: 339.88 | R37: 356.5 | U37: =SUM(I37:T37) -> 1715.36 | W37: {=MMULT(Y37,11)} -> 1572.4133 | X37: =MMULT(Y37,14) -> 2001.2533 | Y37: =U37/12 -> 142.94667
A38: LA COSTANERA | J38: 216.88 | K38: 112.25 | L38: 520.88 | P38: 502.03 | U38: =SUM(I38:T38) -> 1352.04 | W38: {=MMULT(Y38,11)} -> 1239.37 | X38: =MMULT(Y38,14) -> 1577.38 | Y38: =U38/12 -> 112.67
A39: OCEANVIEW | M39: 264.91 | N39: 519.82 | S39: 519.82 | U39: =SUM(I39:T39) -> 1304.55 | W39: {=MMULT(Y39,11)} -> 1195.8375 | X39: =MMULT(Y39,14) -> 1521.975 | Y39: =U39/12 -> 108.7125
A40: RABALAIS BISTRO | J40: 358.4 | K40: 662.49 | U40: =SUM(I40:T40) -> 1020.89 | W40: {=MMULT(Y40,11)} -> 935.81583 | X40: =MMULT(Y40,14) -> 1191.0383 | Y40: =U40/12 -> 85.074167
A41: Key’s Jazz Bistro | S41: 781 | U41: =SUM(I41:T41) -> 781 | W41: {=MMULT(Y41,11)} -> 715.91667 | X41: =MMULT(Y41,14) -> 911.16667 | Y41: =U41/12 -> 65.083333
A42: VIA PICCALO TRATTORIA | K42: 237.17 | L42: 277.6 | P42: 212.52 | U42: =SUM(I42:T42) -> 727.29 | W42: {=MMULT(Y42,11)} -> 666.6825 | X42: =MMULT(Y42,14) -> 848.505 | Y42: =U42/12 -> 60.6075
A43: PHO REAL KITCHEN | J43: 219 | K43: 480 | U43: =SUM(I43:T43) -> 699 | W43: {=MMULT(Y43,11)} -> 640.75 | X43: =MMULT(Y43,14) -> 815.5 | Y43: =U43/12 -> 58.25
A44: FATTORIA E MARE | M44: 529.38 | N44: 162.19 | U44: =SUM(I44:T44) -> 691.57 | W44: {=MMULT(Y44,11)} -> 633.93917 | X44: =MMULT(Y44,14) -> 806.83167 | Y44: =U44/12 -> 57.630833
...

Sheet Revenue - Equipment 2022
A1: Account Name | B1: A/E | C1: CONTACT | D1: EQUIPMENT | E1: NOTES / STATUS | F1: Close Date | G1: Amount | H1: Status | I1: Jan | J1: Feb | K1: Mar | L1: Apr | M1: May | N1: Jun | O1: Jul | P1: Aug | Q1: Sep | R1: Oct | S1: Nov | T1: Dec | U1: TOTAL | W1: Budget | X1: Goal | Y1: AVG/MONTH
A2: *** ONBOARD ***
A4: Antigua Cocina | B4: AH | O4: 1101 | U4: =SUM(I4:T4) -> 1101 | W4: 1002 | X4: 1502 | Y4: =U4/12 -> 91.75
A5: Busters Cheese Steak | B5: AH | D5: Awaiting customer call | E5: NCC | O5: 1500 | U5: =SUM(I5:T5) -> 1500 | W5: 1008 | X5: 1508 | Y5: =U5/12 -> 125
A6: Cafe Greco – 415-397-6261 / 415-990-7613 | B6: AH | O6: 1043.57 | U6: =SUM(I6:T6) -> 1043.57 | W6: 1000 | X6: 1500 | Y6: =U6/12 -> 86.964167
A7: Candy Heaven | B7: AH | I7: 864.56 | U7: =SUM(I7:T7) -> 864.56 | W7: 1010 | X7: 1510 | Y7: =U7/12 -> 72.046667
A8: Cigarettes Cheaper Arcata | B8: AH | C8: Mohammad | D8: Fusion Scanner | E8: 369 | P8: 400.37 | U8: =SUM(I8:T8) -> 400.37 | W8: 1004 | X8: 1504 | Y8: =U8/12 -> 33.364167
A9: Cigarettes Cheaper Arcata | B9: AH | C9: Mohammad | D9: Fusion Scanner | P9: 400.37 | U9: =SUM(I9:T9) -> 400.37 | W9: 1005 | X9: 1505 | Y9: =U9/12 -> 33.364167
A10: Davis Plaza Liquor | J10: 305.2 | U10: =SUM(I10:T10) -> 305.2 | W10: 1016 | X10: 1516 | Y10: =U10/12 -> 25.433333
A11: DEPARTMENT OF AGRICULTURE/WEIGHTS & MEASURES | B11: AH | E11: 3500 | P11: 2045 | U11: =SUM(I11:T11) -> 2045 | W11: 1003 | X11: 1503 | Y11: =U11/12 -> 170.41667
A12: EL CAMARON DE SINALOA | B12: AH | J12: 4844.19 | U12: =SUM(I12:T12) -> 4844.19 | W12: 1011 | X12: 1511 | Y12: =U12/12 -> 403.6825
A13: Grand Express | T13: 5490 | U13: =SUM(I13:T13) -> 5490 | W13: 1000 | X13: 1200 | Y13: =U13/12 -> 457.5
A14: HOUSE OF SOUL | B14: AH | I14: 1214.85 | U14: =SUM(I14:T14) -> 1214.85 | W14: 1013 | X14: 1513 | Y14: =U14/12 -> 101.2375
A15: MURSHED ABDUL | B15: AH | J15: 528.96 | U15: =SUM(I15:T15) -> 528.96 | W15: 1012 | X15: 1512 | Y15: =U15/12 -> 44.08
A16: New Delhi Cuisine | N16: 795 | U16: =SUM(I16:T16) -> 795 | W16: 1015 | X16: 1515 | Y16: =U16/12 -> 66.25
A17: Nieves Mangoman | Q17: 325 | U17: =SUM(I17:T17) -> 325 | W17: 1017 | X17: 1517 | Y17: =U17/12 -> 27.083333
A18: Point Richmond Market | R18: 2390 | U18: =SUM(I18:T18) -> 2390 | W18: 1014 | X18: 1514 | Y18: =U18/12 -> 199.16667
A19: Robata Grill | B19: AH | E19: ALOHA 2 TMU220B | O19: 546.66 | U19: =SUM(I19:T19) -> 546.66 | W19: 1006 | X19: 1506 | Y19: =U19/12 -> 45.555
A20: Smoke City | R20: 495 | U20: =SUM(I20:T20) -> 495 | W20: 1000 | X20: 1200 | Y20: =U20/12 -> 41.25
A21: Soultrans | T21: 4580 | U21: =SUM(I21:T21) -> 4580 | W21: 1000 | X21: 1200 | Y21: =U21/12 -> 381.66667
A22: Syufy | B22: AH | O22: 1048 | U22: =SUM(I22:T22) -> 1048 | W22: 1001 | X22: 1501 | Y22: =U22/12 -> 87.333333
A23: Uncle Sams Liquor | T23: 395 | U23: =SUM(I23:T23) -> 395 | W23: 1000 | X23: 1200 | Y23: =U23/12 -> 32.916667
U24: =SUM(I24:T24) -> 0 | W24: 1007 | X24: 1507 | Y24: =U24/12 -> 0
U25: =SUM(I25:T25) -> 0 | W25: 1009 | X25: 1509 | Y25: =U25/12 -> 0
U26: =SUM(I26:T26) -> 0 | W26: 1000 | X26: 1200 | Y26: =U26/12 -> 0
Y27: =U27/12 -> 0
A28: *** RUNNING TOTAL *** | I28: =SUM(I2:I27) -> 2079.41 | J28: =SUM(J2:J27) -> 5678.35 | K28: =SUM(K2:K27) -> 0 | L28: =SUM(L2:L27) -> 0 | M28: =SUM(M2:M27) -> 0 | N28: =SUM(N2:N27) -> 795 | O28: =SUM(O2:O27) -> 5239.23 | P28: =SUM(P2:P27) -> 2845.74 | ... Y28: =SUM(Y2:Y27) -> 2526.0608
A29: Account Name | B29: A/E | C29: CONTACT | D29: EQUIPMENT | E29: NOTES / STATUS | F29: Close Date | G29: Amount | H29: Status | I29: Jan | J29: Feb | K29: Mar | L29: Apr | M29: May | N29: Jun | O29: Jul | P29: Aug | Q29: Sep | R29: Oct | S29: Nov | T29: Dec | U29: TOTAL | W29: Budget | X29: Goal | Y29: AVG/MONTH
A30: TACOS SINALOA | B30: AH | D30: NCC (3) | E30: sold | M30: 7010 | U30: =SUM(I30:T30) -> 7010 | W30: 1021 | X30: 1221 | Y30: =U30/12 -> 584.16667
A31: STONY POINT MARKET | B31: AH | C31: Tony | D31: Sam4s SAP6600 | E31: sold | G31: 4200 | R31: 5950 | U31: =SUM(I31:T31) -> 5950 | W31: 1041 | X31: 1241 | Y31: =U31/12 -> 495.83333
A32: San Pablo Market | B32: AH | E32: sold | T32: 5715 | U32: =SUM(I32:T32) -> 5715 | W32: 1019 | X32: 1219 | Y32: =U32/12 -> 476.25
A33: GRAND EXPRESS | B33: AH | D33: tablet | E33: sold | L33: 3212 | T33: 1590 | U33: =SUM(I33:T33) -> 4802 | W33: 1015 | X33: 1215 | Y33: =U33/12 -> 400.16667
A34: STONY POINT MARKET | B34: AH | D34: SAM4S SAP6600 | E34: sold | J34: 2745 | U34: =SUM(I34:T34) -> 2745 | W34: 1002 | X34: 1202 | Y34: =U34/12 -> 228.75
A35: EL MAZATLECO | B35: AH | D35: NCC-2 | E35: sold | J35: 2150 | U35: =SUM(I35:T35) -> 2150 | W35: 1000 | X35: 1200 | Y35: =U35/12 -> 179.16667
A36: SANCHO'S TAQUERIA | B36: AH | D36: NCC-1 | E36: sold | J36: 2050 | U36: =SUM(I36:T36) -> 2050 | W36: 1000 | X36: 1200 | Y36: =U36/12 -> 170.83333
A37: WEST WIND | B37: AH | D37: ER-940 | E37: sold | P37: 995 | R37: 945 | U37: =SUM(I37:T37) -> 1940 | W37: 1033 | X37: 1233 | Y37: =U37/12 -> 161.66667
A38: Star Grocery | B38: AH | E38: sold | R38: 1790 | U38: =SUM(I38:T38) -> 1790 | W38: 1053 | X38: 1253 | Y38: =U38/12 -> 149.16667
A39: STONY POINT MARKET | B39: AH | C39: Tony | D39: Sam4s SAP6600 | E39: sold | G39: 1553.16 | R39: 1553.16 | U39: =SUM(I39:T39) -> 1553.16 | W39: 1040 | X39: 1240 | Y39: =U39/12 -> 129.43
A40: La Hacienda | B40: AH | C40: Armando | D40: NCC -1 | E40: sold | S40: 1538 | U40: =SUM(I40:T40) -> 1538 | W40: 1039 | X40: 1239 | Y40: =U40/12 -> 128.16667
A41: SOULTRANS SEAFOOD | B41: AH | D41: Scanner | E41: sold | P41: 1535 | U41: =SUM(I41:T41) -> 1535 | W41: 1036 | X41: 1236 | Y41: =U41/12 -> 127.91667
...

Sheet Revnue - NAHSO Supplies_2022
A1: Account Name | B1: A/E | C1: CONTACT | D1: EQUIPMENT | E1: NOTES / STATUS | F1: Close Date | G1: Amount | H1: Status | I1: Jan | J1: Feb | K1: Mar | L1: Apr | M1: May | N1: Jun | O1: Jul | P1: Aug | Q1: Sep | R1: Oct | S1: Nov | T1: Dec | U1: TOTAL | W1: Budget | X1: Goal | Y1: AVG/MONTH
A2: *** ONBOARD ***
A3: COASTAL PACIFIC | L3: 919 | M3: 1302 | N3: 918 | O3: 779 | P3: 1027 | Q3: 2310 | R3: 2228 | S3: 690 | T3: 1035 | U3: =SUM(I3:T3) -> 11208 | W3: {=MMULT(Y3,11)} -> 10274 | X3: {=MMULT(Y3,14)} -> 13076 | Y3: =U3/12 -> 934
A4: CASS INC | O4: 6258.84 | U4: =SUM(I4:T4) -> 6258.84 | W4: {=MMULT(Y4,11)} -> 5737.27 | X4: {=MMULT(Y4,14)} -> 7301.98 | Y4: =U4/12 -> 521.57
A5: SOL FOOD COMMISSARY | I5: 2075 | O5: 1650 | S5: 2250 | U5: =SUM(I5:T5) -> 5975 | W5: {=MMULT(Y5,11)} -> 5477.0833 | X5: {=MMULT(Y5,14)} -> 6970.8333 | Y5: =U5/12 -> 497.91667
A6: SOL FOOD | L6: 1639 | N6: 1350 | Q6: 2175 | U6: =SUM(I6:T6) -> 5164 | W6: {=MMULT(Y6,11)} -> 4733.6667 | X6: {=MMULT(Y6,14)} -> 6024.6667 | Y6: =U6/12 -> 430.33333
A7: CASA LUPE | I7: 550 | L7: 708 | O7: 1670 | Q7: 650 | S7: 1340 | U7: =SUM(I7:T7) -> 4918 | W7: {=MMULT(Y7,11)} -> 4508.1667 | X7: {=MMULT(Y7,14)} -> 5737.6667 | Y7: =U7/12 -> 409.83333
A8: BOH-WILDSEED | I8: 612 | J8: 411 | K8: 352 | L8: 460 | M8: 285 | O8: 918 | P8: 117 | Q8: 715 | R8: 405 | T8: 139 | U8: =SUM(I8:T8) -> 4414 | W8: {=MMULT(Y8,11)} -> 4046.1667 | X8: {=MMULT(Y8,14)} -> 5149.6667 | Y8: =U8/12 -> 367.83333
A9: COASTAL PACIFIC | L9: 365 | M9: 690 | N9: 552 | O9: 483 | P9: 207 | Q9: 711 | R9: 690 | U9: =SUM(I9:T9) -> 3698 | W9: {=MMULT(Y9,11)} -> 3389.8333 | X9: {=MMULT(Y9,14)} -> 4314.3333 | Y9: =U9/12 -> 308.16667
A10: CALISTOGA INN | I10: 135 | J10: 100 | K10: 303 | L10: 255 | M10: 165 | N10: 1101 | O10: 198 | P10: 408 | Q10: 276 | R10: 363 | S10: 198 | T10: 165 | U10: =SUM(I10:T10) -> 3667 | W10: {=MMULT(Y10,11)} -> 3361.4167 | X10: {=MMULT(Y10,14)} -> 4278.1667 | Y10: =U10/12 -> 305.58333
A11: COASTAL PACIFIC | N11: 276 | O11: 730 | P11: 828 | Q11: 552 | R11: 790 | S11: 392 | U11: =SUM(I11:T11) -> 3568 | W11: {=MMULT(Y11,11)} -> 3270.6667 | X11: {=MMULT(Y11,14)} -> 4162.6667 | Y11: =U11/12 -> 297.33333
A12: WATERBAR | J12: 615 | L12: 891 | P12: 1089 | R12: 914 | T12: 729 | U12: =SUM(I12:T12) -> 4238 | W12: {=MMULT(Y12,11)} -> 3884.8333 | X12: {=MMULT(Y12,14)} -> 4944.3333 | Y12: =U12/12 -> 353.16667
A13: MARINA SUPER | N13: 410 | P13: 885 | R13: 406 | S13: 674 | T13: 674 | U13: =SUM(I13:T13) -> 3049 | W13: {=MMULT(Y13,11)} -> 2794.9167 | X13: {=MMULT(Y13,14)} -> 3557.1667 | Y13: =U13/12 -> 254.08333
A14: COASTAL PACIFIC | L14: 406 | M14: 86 | N14: 305 | O14: 345 | R14: 474 | S14: 1422 | U14: =SUM(I14:T14) -> 3038 | W14: {=MMULT(Y14,11)} -> 2784.8333 | X14: {=MMULT(Y14,14)} -> 3544.3333 | Y14: =U14/12 -> 253.16667
A15: ROKA AKOR | I15: 296 | J15: 55 | K15: 293 | L15: 94 | M15: 486 | N15: 454 | P15: 180 | Q15: 454 | R15: 156 | S15: 337 | T15: 180 | U15: =SUM(I15:T15) -> 2985 | W15: {=MMULT(Y15,11)} -> 2736.25 | X15: {=MMULT(Y15,14)} -> 3482.5 | Y15: =U15/12 -> 248.75
A16: EPIC STEAK | L16: 1447 | O16: 442 | P16: 945 | U16: =SUM(I16:T16) -> 2834 | W16: {=MMULT(Y16,11)} -> 2597.8333 | X16: {=MMULT(Y16,14)} -> 3306.3333 | Y16: =U16/12 -> 236.16667
A17: HARVEST MARKET | R17: 990 | S17: 1650 | U17: =SUM(I17:T17) -> 2640 | W17: {=MMULT(Y17,11)} -> 2420 | X17: {=MMULT(Y17,14)} -> 3080 | Y17: =U17/12 -> 220
A18: VILLAGE MARKET & PIZZA | K18: 675 | P18: 977 | Q18: 985 | U18: =SUM(I18:T18) -> 2637 | W18: {=MMULT(Y18,11)} -> 2417.25 | X18: {=MMULT(Y18,14)} -> 3076.5 | Y18: =U18/12 -> 219.75
A19: POGGIO | J19: 490 | O19: 862 | Q19: 440 | S19: 784 | U19: =SUM(I19:T19) -> 2576 | W19: {=MMULT(Y19,11)} -> 2361.3333 | X19: {=MMULT(Y19,14)} -> 3005.3333 | Y19: =U19/12 -> 214.66667
A20: STARK'S STEAKHOUSE | I20: 157 | J20: 145 | K20: 157 | L20: 157 | M20: 298 | N20: 285 | O20: 308 | P20: 243 | Q20: 240 | R20: 175 | S20: 298 | U20: =SUM(I20:T20) -> 2463 | W20: {=MMULT(Y20,11)} -> 2257.75 | X20: {=MMULT(Y20,14)} -> 2873.5 | Y20: =U20/12 -> 205.25
A21: TAQUERIA EL GORDO | K21: 590 | L21: 707 | S21: 914 | U21: =SUM(I21:T21) -> 2211 | W21: {=MMULT(Y21,11)} -> 2026.75 | X21: {=MMULT(Y21,14)} -> 2579.5 | Y21: =U21/12 -> 184.25
A22: INSALATA'S | J22: 262 | K22: 225 | L22: 451 | N22: 130 | P22: 90 | Q22: 345 | R22: 78 | S22: 590 | U22: =SUM(I22:T22) -> 2171 | W22: {=MMULT(Y22,11)} -> 1990.0833 | X22: {=MMULT(Y22,14)} -> 2532.8333 | Y22: =U22/12 -> 180.91667
A23: UNCLE YU'S | L23: 1180 | S23: 975 | U23: =SUM(I23:T23) -> 2155 | W23: {=MMULT(Y23,11)} -> 1975.4167 | X23: {=MMULT(Y23,14)} -> 2514.1667 | Y23: =U23/12 -> 179.58333
A24: COCO'S MERCADO | I24: 168 | J24: 139 | K24: 145 | L24: 149 | M24: 222 | N24: 255 | P24: 326 | Q24: 118 | R24: 287 | S24: 255 | U24: =SUM(I24:T24) -> 2064 | W24: {=MMULT(Y24,11)} -> 1892 | X24: {=MMULT(Y24,14)} -> 2408 | Y24: =U24/12 -> 172
A25: THE CANTINA | I25: 297 | J25: 176 | L25: 235 | M25: 130 | O25: 312 | P25: 298 | Q25: 285 | S25: 324 | U25: =SUM(I25:T25) -> 2057 | W25: {=MMULT(Y25,11)} -> 1885.5833 | X25: {=MMULT(Y25,14)} -> 2399.8333 | Y25: =U25/12 -> 171.41667
A26: 5TH ST STEAKHOUSE | J26: 136 | K26: 205 | L26: 234 | N26: 320 | O26: 304 | P26: 223 | Q26: 168 | S26: 457 | U26: =SUM(I26:T26) -> 2047 | W26: {=MMULT(Y26,11)} -> 1876.4167 | X26: {=MMULT(Y26,14)} -> 2388.1667 | Y26: =U26/12 -> 170.58333
A27: THE TRIDENT | K27: 470 | O27: 781 | S27: 726 | U27: =SUM(I27:T27) -> 1977 | W27: {=MMULT(Y27,11)} -> 1812.25 | X27: {=MMULT(Y27,14)} -> 2306.5 | Y27: =U27/12 -> 164.75
A28: FARMHOUSE LOCAL | I28: 55 | K28: 275 | L28: 353 | M28: 338 | N28: 130 | O28: 363 | Q28: 298 | R28: 130 | U28: =SUM(I28:T28) -> 1942 | W28: {=MMULT(Y28,11)} -> 1780.1667 | X28: {=MMULT(Y28,14)} -> 2265.6667 | Y28: =U28/12 -> 161.83333
A29: FISH | J29: 572 | L29: 490 | P29: 480 | S29: 290 | U29: =SUM(I29:T29) -> 1832 | W29: {=MMULT(Y29,11)} -> 1679.3333 | X29: {=MMULT(Y29,14)} -> 2137.3333 | Y29: =U29/12 -> 152.66667
A30: BARREL HOUSE TAVERN | I30: 270 | L30: 390 | Q30: 1170 | U30: =SUM(I30:T30) -> 1830 | W30: {=MMULT(Y30,11)} -> 1677.5 | X30: {=MMULT(Y30,14)} -> 2135 | Y30: =U30/12 -> 152.5
A31: BUNGALOW 44 | I31: 411 | K31: 216 | N31: 350 | P31: 451 | S31: 315 | U31: =SUM(I31:T31) -> 1743 | W31: {=MMULT(Y31,11)} -> 1597.75 | X31: {=MMULT(Y31,14)} -> 2033.5 | Y31: =U31/12 -> 145.25
A32: MI RANCHO MARKET | I32: 165 | J32: 90 | K32: 153 | L32: 223 | M32: 130 | N32: 130 | O32: 143 | P32: 169 | Q32: 143 | R32: 78 | S32: 169 | T32: 65 | U32: =SUM(I32:T32) -> 1658 | W32: {=MMULT(Y32,11)} -> 1519.8333 | X32: {=MMULT(Y32,14)} -> 1934.3333 | Y32: =U32/12 -> 138.16667
A33: ROSE'S CAFÉ | I33: 294 | K33: 314 | N33: 354 | Q33: 399 | T33: 289 | U33: =SUM(I33:T33) -> 1650 | W33: {=MMULT(Y33,11)} -> 1512.5 | X33: {=MMULT(Y33,14)} -> 1925 | Y33: =U33/12 -> 137.5
A34: GUERRA QUALITY MEATS | L34: 195 | M34: 483 | O34: 483 | P34: 483 | U34: =SUM(I34:T34) -> 1644 | W34: {=MMULT(Y34,11)} -> 1507 | X34: {=MMULT(Y34,14)} -> 1918 | Y34: =U34/12 -> 137
A35: STATE BIRD | J35: 162 | K35: 108 | L35: 176 | M35: 159 | N35: 149 | O35: 159 | P35: 149 | Q35: 269 | S35: 308 | U35: =SUM(I35:T35) -> 1639 | W35: {=MMULT(Y35,11)} -> 1502.4167 | X35: {=MMULT(Y35,14)} -> 1912.1667 | Y35: =U35/12 -> 136.58333
A36: EVERGREEN PRODUCE | L36: 745 | P36: 884 | U36: =SUM(I36:T36) -> 1629 | W36: {=MMULT(Y36,11)} -> 1493.25 | X36: {=MMULT(Y36,14)} -> 1900.5 | Y36: =U36/12 -> 135.75
A37: MONTI'S ROTISSERIE | J37: 452 | M37: 410 | N37: 260 | R37: 450 | U37: =SUM(I37:T37) -> 1572 | W37: {=MMULT(Y37,11)} -> 1441 | X37: {=MMULT(Y37,14)} -> 1834 | Y37: =U37/12 -> 131
A38: LEFT BANK | I38: 248 | J38: 307 | K38: 236 | M38: 260 | P38: 195 | S38: 325 | U38: =SUM(I38:T38) -> 1571 | W38: {=MMULT(Y38,11)} -> 1440.0833 | X38: {=MMULT(Y38,14)} -> 1832.8333 | Y38: =U38/12 -> 130.91667
A39: GUEST HOUSE | J39: 223 | M39: 304 | O39: 269 | P39: 441 | T39: 324 | U39: =SUM(I39:T39) -> 1561 | W39: {=MMULT(Y39,11)} -> 1430.9167 | X39: {=MMULT(Y39,14)} -> 1821.1667 | Y39: =U39/12 -> 130.08333
A40: GROSSMAN'S NOSHERY | I40: 270 | K40: 196 | L40: 214 | N40: 220 | Q40: 220 | R40: 175 | T40: 220 | U40: =SUM(I40:T40) -> 1515 | W40: {=MMULT(Y40,11)} -> 1388.75 | X40: {=MMULT(Y40,14)} -> 1767.5 | Y40: =U40/12 -> 126.25
...

Sheet Revnue - Service 2022
A1: Account Name | B1: A/E | C1: CONTACT | D1: EQUIPMENT | E1: NOTES / STATUS | F1: Close Date | G1: Amount | H1: Status | I1: Jan | J1: Feb | K1: Mar | L1: Apr | M1: May | N1: Jun | O1: Jul | P1: Aug | Q1: Sep | R1: Oct | S1: Nov | T1: Dec | U1: TOTAL | W1: Budget | X1: Goal | Y1: AVG/MONTH
A2: *** ONBOARD ***
A4: Oak Park Liquor | B4: AH | C4: LG | O4: 450 | U4: =SUM(I4:T4) -> 450 | W4: 300 | X4: 500 | Y4: =U4/12 -> 37.5
A5: Point Richmond Market | R5: 720 | U5: =SUM(I5:T5) -> 720
A6: Geary & Hyde Market | B6: AH | C6: EL | D6: In repair bay | E6: Andy Patel – 415-760-9315 | O6: 360 | U6: =SUM(I6:T6) -> 360 | W6: 300 | X6: 500 | Y6: =U6/12 -> 30
A7: KAFFE MOCHA & GRILL | J7: 270 | P7: 45 | U7: =SUM(I7:T7) -> 315 | Y7: =U7/12 -> 26.25
A8: DISCOUNT ALLEY | U8: =SUM(I8:T8) -> 0 | W8: 300 | X8: 500 | Y8: =U8/12 -> 0
A9: DEPARTMENT OF AGRICULTURE/WEIGHTS & MEASURES | B9: AH | E9: 3500 | P9: 750 | U9: =SUM(I9:T9) -> 750 | Y9: =U9/12 -> 62.5
A10: DEPARTMENT OF AGRICULTURE/WEIGHTS & MEASURES | B10: AH | E10: 3500 | P10: 180 | U10: =SUM(I10:T10) -> 180 | Y10: =U10/12 -> 15
A11: Nieves Mangoman | Q11: 90 | U11: =SUM(I11:T11) -> 90
A12: DEPARTMENT OF AGRICULTURE/WEIGHTS & MEASURES | B12: AH | E12: Travel | Q12: 180 | U12: =SUM(I12:T12) -> 180 | Y12: =U12/12 -> 15
A13: DEPARTMENT OF AGRICULTURE/WEIGHTS & MEASURES | B13: AH | E13: Onsite | Q13: 1260 | U13: =SUM(I13:T13) -> 1260 | Y13: =U13/12 -> 105
Y14: =U14/12 -> 0
A15: *** RUNNING TOTAL *** | B15: 2021 | I15: =SUM(I2:I14) -> 0 | J15: =SUM(J2:J14) -> 270 | K15: =SUM(K2:K14) -> 0 | L15: =SUM(L2:L14) -> 0 | M15: =SUM(M2:M14) -> 0 | N15: =SUM(N2:N14) -> 0 | O15: =SUM(O2:O14) -> 810 | P15: =SUM(P2:P14) -> 975 | ... X15: =SUM(X2:X14) -> 1500 | Y15: =U15/12 -> 358.75
A17: DEPARTMENT OF AGRICULTURE/WEIGHTS & MEASURES | N17: 1980 | U17: =SUM(I17:T17) -> 1980 | W17: {=MMULT(Y17,11)} -> 1815 | X17: {=MMULT(Y17,14)} -> 2310 | Y17: =U17/12 -> 165
A18: THERESA & JOHNNY'S | N18: 1440 | U18: =SUM(I18:T18) -> 1440 | W18: {=MMULT(Y18,11)} -> 1320 | X18: {=MMULT(Y18,14)} -> 1680 | Y18: =U18/12 -> 120
A19: STONY POINT MARKET | D19: SAM4S SAP6600 | I19: 720 | R19: 360 | U19: =SUM(I19:T19) -> 1080 | W19: {=MMULT(Y19,11)} -> 990 | X19: {=MMULT(Y19,14)} -> 1260 | Y19: =U19/12 -> 90
A20: San Pablo Market | T20: 990 | U20: =SUM(I20:T20) -> 990 | W20: {=MMULT(Y20,11)} -> 907.5 | X20: {=MMULT(Y20,14)} -> 1155 | Y20: =U20/12 -> 82.5
A21: La Hacienda | B21: AH | C21: Armando | D21: NCC-1 | E21: Reconditioned | F21: 44873 | S21: 810 | U21: =SUM(I21:T21) -> 810 | W21: {=MMULT(Y21,11)} -> 742.5 | X21: {=MMULT(Y21,14)} -> 945 | Y21: =U21/12 -> 67.5
A22: 420 SMOKE PALACE | I22: 795 | U22: =SUM(I22:T22) -> 795 | W22: {=MMULT(Y22,11)} -> 728.75 | X22: {=MMULT(Y22,14)} -> 927.5 | Y22: =U22/12 -> 66.25
A23: STAR GROCERY | O23: 360 | R23: 360 | U23: =SUM(I23:T23) -> 720 | W23: {=MMULT(Y23,11)} -> 660 | X23: {=MMULT(Y23,14)} -> 840 | Y23: =U23/12 -> 60
A24: Donut King | S24: 540 | U24: =SUM(I24:T24) -> 540 | W24: {=MMULT(Y24,11)} -> 495 | X24: {=MMULT(Y24,14)} -> 630 | Y24: =U24/12 -> 45
A25: GRAND EXPRESS | L25: 360 | T25: 170 | U25: =SUM(I25:T25) -> 530 | W25: {=MMULT(Y25,11)} -> 485.83333 | X25: {=MMULT(Y25,14)} -> 618.33333 | Y25: =U25/12 -> 44.166667
A26: STONY POINT MARKET | D26: SAM4S SAP6600 | R26: 495 | U26: =SUM(I26:T26) -> 495 | W26: {=MMULT(Y26,11)} -> 453.75 | X26: {=MMULT(Y26,14)} -> 577.5 | Y26: =U26/12 -> 41.25
A27: POINT RICHMOND MARKET | P27: 405 | U27: =SUM(I27:T27) -> 405 | W27: {=MMULT(Y27,11)} -> 371.25 | X27: {=MMULT(Y27,14)} -> 472.5 | Y27: =U27/12 -> 33.75
A28: U SAVE LIQUOR | I28: 395 | U28: =SUM(I28:T28) -> 395 | W28: {=MMULT(Y28,11)} -> 362.08333 | X28: {=MMULT(Y28,14)} -> 460.83333 | Y28: =U28/12 -> 32.916667
A29: EL MAZATLECO | B29: AH | C29: AH | D29: NCC-2 | I29: 360 | U29: =SUM(I29:T29) -> 360 | W29: {=MMULT(Y29,11)} -> 330 | X29: {=MMULT(Y29,14)} -> 420 | Y29: =U29/12 -> 30
A30: HAPPY TACO | P30: 360 | U30: =SUM(I30:T30) -> 360 | W30: {=MMULT(Y30,11)} -> 330 | X30: {=MMULT(Y30,14)} -> 420 | Y30: =U30/12 -> 30
A31: PETRIFIED FOREST GIFT SHOP | I31: 360 | U31: =SUM(I31:T31) -> 360 | W31: {=MMULT(Y31,11)} -> 330 | X31: {=MMULT(Y31,14)} -> 420 | Y31: =U31/12 -> 30
A32: SPRINGSTOWNE BOTTLE SHOP | I32: 360 | U32: =SUM(I32:T32) -> 360 | W32: {=MMULT(Y32,11)} -> 330 | X32: {=MMULT(Y32,14)} -> 420 | Y32: =U32/12 -> 30
A33: TAQUERIA EL TEJABAN | I33: 360 | U33: =SUM(I33:T33) -> 360 | W33: {=MMULT(Y33,11)} -> 330 | X33: {=MMULT(Y33,14)} -> 420 | Y33: =U33/12 -> 30
A34: TAQUERIA EL TEJABAN | I34: 360 | U34: =SUM(I34:T34) -> 360 | W34: {=MMULT(Y34,11)} -> 330 | X34: {=MMULT(Y34,14)} -> 420 | Y34: =U34/12 -> 30
A35: TAQUERIA EL TEJABAN | K35: 360 | U35: =SUM(I35:T35) -> 360 | W35: {=MMULT(Y35,11)} -> 330 | X35: {=MMULT(Y35,14)} -> 420 | Y35: =U35/12 -> 30
A36: US LIQUOR | D36: ONSITE SVC | J36: 360 | U36: =SUM(I36:T36) -> 360 | W36: {=MMULT(Y36,11)} -> 330 | X36: {=MMULT(Y36,14)} -> 420 | Y36: =U36/12 -> 30
A37: WEST WIND | P37: 360 | U37: =SUM(I37:T37) -> 360 | W37: {=MMULT(Y37,11)} -> 330 | X37: {=MMULT(Y37,14)} -> 420 | Y37: =U37/12 -> 30
A38: WEST WIND | R38: 360 | U38: =SUM(I38:T38) -> 360 | W38: {=MMULT(Y38,11)} -> 330 | X38: {=MMULT(Y38,14)} -> 420 | Y38: =U38/12 -> 30
A39: LAS MONTANAS | M39: 345 | U39: =SUM(I39:T39) -> 345 | W39: {=MMULT(Y39,11)} -> 316.25 | X39: {=MMULT(Y39,14)} -> 402.5 | Y39: =U39/12 -> 28.75
A40: Ace Hardware | B40: AH | D40: ER-260 | Q40: 270 | U40: =SUM(I40:T40) -> 270 | W40: {=MMULT(Y40,11)} -> 247.5 | X40: {=MMULT(Y40,14)} -> 315 | Y40: =U40/12 -> 22.5
A41: POINT RICHMOND MARKET & DELI | L41: 270 | U41: =SUM(I41:T41) -> 270 | W41: {=MMULT(Y41,11)} -> 247.5 | X41: {=MMULT(Y41,14)} -> 315 | Y41: =U41/12 -> 22.5
A42: SANCHO'S TAQUERIA | K42: 270 | U42: =SUM(I42:T42) -> 270 | W42: {=MMULT(Y42,11)} -> 247.5 | X42: {=MMULT(Y42,14)} -> 315 | Y42: =U42/12 -> 22.5
...

Sheet Upcoming Installations
A1: Name | B1: Status | C1: Street Address | D1: City | E1: State | F1: Zipcode | G1: PM | H1: Status | I1: Accepted On | J1: Agent | M1: Merchant Id | N1: Profile Link | T1: MID
A3: Ancora | B3: In-Process | C3: 557 Valencia St | D3: San Francisco | E3: CA | F3: 94110 | H3: site walk- dk-5/2 | I3: 44651.339 | J3: Youkilis Scott | M3: 624637999adef3fc5a37f781 | N3: https://hub.spoton.com/merchants/624637999adef3fc5a37f781 | T3: 545500001565340
A4: Andy and Yu's Restaurant and Bar | B4: Pre-Cancellation | C4: 348 Saint Mary St | D4: Pleasanton | E4: CA | F4: 94566 | I4: 44438.639 | J4: Koidal Steve | M4: 612d59c29adef36e02168ad1 | N4: https://hub.spoton.com/merchants/612d59c29adef36e02168ad1 | T4: 545500001442300
A5: Arya Steakhouse | B5: In-Process | C5: 885 Middlefield Rd | D5: Redwood City | E5: CA | F5: 94063 | I5: 44657.537 | J5: Walker Stephen | M5: 624e16d424b4c44267b02422 | N5: https://hub.spoton.com/merchants/624e16d424b4c44267b02422 | T5: 545500001569110
A6: Asian Box (Airport Terminal G) | B6: Pending Active | C6: 7805 Airport Blvd Terminal G G.3 019 D | D6: San Francisco | E6: CA | F6: 94128 | G6: LG | H6: install 5/10? | I6: 44505.493 | J6: Transact SpotOn | M6: 6185af3524b4c46b8afc10ee | N6: https://hub.spoton.com/merchants/6185af3524b4c46b8afc10ee | T6: 545500001484658
A7: Autumn Room | B7: In-Process | C7: 2367 El Camino Real | D7: Santa Clara | E7: CA | F7: 95050 | I7: 44567.373 | J7: =- david zepnick cloud pos solutions -> #VALUE! | M7: 61d7596524b4c47dfb60cfdd | N7: https://hub.spoton.com/merchants/61d7596524b4c47dfb60cfdd | T7: 545500001516178
A8: Babette | B8: Pending Active | C8: 2033 San Pablo Ave | D8: Berkeley | E8: CA | F8: 94702 | G8: TP | H8: install 5/9? | I8: 44603.662 | J8: Walker Stephen | M8: 620ad2ee9adef37ad70ae3fe | N8: https://hub.spoton.com/merchants/620ad2ee9adef37ad70ae3fe | T8: 545500001537216
A9: Bergerac | B9: In-Process | C9: 316 11th St | D9: San Francisco | E9: CA | F9: 94103 | I9: 44651.344 | J9: O'Brien Dave | M9: 6245c81c9adef3c048b94bc6 | N9: https://hub.spoton.com/merchants/6245c81c9adef3c048b94bc6 | T9: 545500001564392
A10: Birrieria Jalisco | B10: Pending Active | C10: 1546 S El Dorado St | D10: Stockton | E10: CA | F10: 95206 | I10: 44662.572 | J10: =- jason geraci datasciencx -> #VALUE! | M10: 6254c4e99adef3075189bb89 | N10: https://hub.spoton.com/merchants/6254c4e99adef3075189bb89 | T10: 545500001571926
A11: Bonita Taqueria + Rotisserie - Polk | B11: Pending Active | C11: 2227 Polk St | D11: San Francisco | E11: CA | F11: 94109 | G11: JC | H11: installed? | I11: 44574.541 | J11: Massis Nimer | M11: 61e0bbae24b4c4347fb800d1 | N11: https://hub.spoton.com/merchants/61e0bbae24b4c4347fb800d1 | T11: 545500001519768
A12: Burmatown | B12: Pre-Cancellation | C12: 18 Tamalpais Dr | D12: Corte Madera | E12: CA | F12: 94925 | I12: 44322.406 | J12: Carter Suzie | M12: 609485dc24b4c47d64715fa2 | N12: https://hub.spoton.com/merchants/609485dc24b4c47d64715fa2 | T12: 545500001373745
A13: Cafe Rosso | B13: Pending Active | C13: 1600 Holloway Ave | D13: San Francisco | E13: CA | F13: 94132 | I13: 44396.435 | J13: Massis Nimer | M13: 60f5ba7224b4c42ae0ff9e10 | N13: https://hub.spoton.com/merchants/60f5ba7224b4c42ae0ff9e10 | T13: 545500001415926
A14: Cantina Los Mayas | B14: In-Process | C14: 431 Balboa St | D14: San Francisco | E14: CA | F14: 94118 | I14: 44684.425 | J14: Lakritz Noah | M14: 62729cd09adef381b945c463 | N14: https://hub.spoton.com/merchants/62729cd09adef381b945c463 | T14: 545500001586247
A15: Curry Leaves Bistro | B15: In-Process | C15: 6003 W Las Positas Blvd | D15: Pleasanton | E15: CA | F15: 94588 | I15: 44662.454 | J15: Lajoie Sarah | M15: 6254a2c424b4c40daaa6c748 | N15: https://hub.spoton.com/merchants/6254a2c424b4c40daaa6c748 | T15: 545500001571686
A16: Danville Brewing Co | B16: In-Process | C16: 200 Railroad Ave | D16: Danville | E16: CA | F16: 94526 | I16: 44679.551 | J16: O'Brien Dave | M16: 626b2ba89adef3d39b241710 | N16: https://hub.spoton.com/merchants/626b2ba89adef3d39b241710 | T16: 545500001582667
A17: Don Rubens Restaurant | B17: Pre-Cancellation | C17: 5109 Hwy 140 | D17: Mariposa | E17: CA | F17: 95338 | I17: 44386.607 | J17: Walburn David | M17: 60e8d01924b4c45d64f19cbd | N17: https://hub.spoton.com/merchants/60e8d01924b4c45d64f19cbd | T17: 545500001411362
A18: Donato & Company | B18: Pending Active | C18: 2635 Ashby Ave | D18: Berkeley | E18: CA | F18: 94705 | I18: 44484.721 | J18: Walker Stephen | M18: 616de0649adef3c99e79c940 | N18: https://hub.spoton.com/merchants/616de0649adef3c99e79c940 | T18: 545500001471325
A19: El Amigo Restaurant | B19: Pre-Cancellation | C19: 13700 Doolittle Dr | D19: San Leandro | E19: CA | F19: 94577 | I19: 44404.525 | J19: Villanueva Daniel | M19: 6100901b9adef3a3e412fb14 | N19: https://hub.spoton.com/merchants/6100901b9adef3a3e412fb14 | T19: 545500001421338
A20: El Brinquito Restaurant | B20: Pre-Cancellation | C20: 810 Piner Rd Ste A | D20: Santa Rosa | E20: CA | F20: 95403 | I20: 44543.649 | J20: Gallegos David | M20: 61ba891324b4c4485e9b1388 | N20: https://hub.spoton.com/merchants/61ba891324b4c4485e9b1388 | T20: 545500001505502
A21: El Kora Restaurant | B21: Pre-Cancellation | C21: 153 Griffin St | D21: Salinas | E21: CA | F21: 93901 | I21: 44544.541 | J21: Dunn Daniel | M21: 61ba2e589adef3d6ca38efc7 | N21: https://hub.spoton.com/merchants/61ba2e589adef3d6ca38efc7 | T21: 545500001505023
A22: El Portal Cocina Mariscos | B22: In-Process | C22: 2108 Story Rd | D22: San Jose | E22: CA | F22: 95122 | I22: 44657.478 | J22: Patterson Aaron | M22: 624ddc1924b4c4267e87b6d2 | N22: https://hub.spoton.com/merchants/624ddc1924b4c4267e87b6d2 | T22: 545500001568716
A23: El Rancho Grande Taqueria | B23: In-Process | C23: 855 Divisadero St | D23: San Francisco | E23: CA | F23: 94117 | I23: 44627.688 | J23: Lakritz Noah | M23: 6227c39224b4c4070ef09014 | N23: https://hub.spoton.com/merchants/6227c39224b4c4070ef09014 | T23: 545500001549955
... A27: Fogo de Minas Steakhouse | B27: In-Process | C27: 2606 Gateway Oaks Dr | D27: Sacramento | E27: CA | F27: 95833 | I27: 44602.621 | J27: Campo Cunha Andre Rennes | M27: 6206994524b4c4168d934840 | N27: https://hub.spoton.com/merchants/6206994524b4c4168d934840 | T27: 545500001535798
A28: Gusto Pinsa Romana | B28: Pending Active | C28: 1000 Bush St | D28: San Francisco | E28: CA | F28: 94109 | I28: 44601.496 | J28: =- dulce castellanos quality solutions -> #VALUE! | M28: 6204594324b4c47f631fb6c2 | N28: https://hub.spoton.com/merchants/6204594324b4c47f631fb6c2 | T28: 545500001534874
A29: Hasu Teriyaki & Sushi | B29: In-Process | C29: 25075 Blue Ravine Rd | D29: Folsom | E29: CA | F29: 95630 | I29: 44616.467 | J29: Ludovina Danny | M29: 6217e5529adef35f92695511 | N29: https://hub.spoton.com/merchants/6217e5529adef35f92695511 | T29: 545500001543123
A30: Hazie's | B30: In-Process | C30: 501 Hayes St | D30: San Francisco | E30: CA | F30: 94102 | I30: 44662.453 | J30: Youkilis Scott | M30: 62546b329adef31eeaee7da1 | N30: https://hub.spoton.com/merchants/62546b329adef31eeaee7da1 | T30: 545500001571355
A31: Headlands Brewing Co. | B31: In-Process | C31: 3420 Mt Diablo Blvd Ste A | D31: Lafayette | E31: CA | F31: 94549 | I31: 44544.435 | J31: Pierce Mike | M31: 61ba32fa9adef3d6ca38f045 | N31: https://hub.spoton.com/merchants/61ba32fa9adef3d6ca38f045 | T31: 545500001505056
A32: House of Prime Rib | B32: In-Process | C32: 1906 Van Ness Ave | D32: San Francisco | E32: CA | F32: 94109 | H32: train 5/9 onsite | I32: 44603.419 | J32: Alden Rich | M32: 6206f25324b4c4316ec485ea | N32: https://hub.spoton.com/merchants/6206f25324b4c4316ec485ea | T32: 545500001536432
A33: Indie Superette | B33: Pre-Cancellation | C33: 3060 Fillmore St | D33: San Francisco | E33: CA | F33: 94123 | I33: 44336.553 | J33: Ouellette Chrissy | M33: 60ac2e8b9adef39ed82af636 | N33: https://hub.spoton.com/merchants/60ac2e8b9adef39ed82af636 | T33: 545500001383017
A34: Insalata's Restaurant | B34: In-Process | C34: 120 Sir Francis Drake Blvd | D34: San Anselmo | E34: CA | F34: 94960 | I34: 44658.674 | J34: Kelly Doug | M34: 6250c3df24b4c46aa6d0679f | N34: https://hub.spoton.com/merchants/6250c3df24b4c46aa6d0679f | T34: 545500001571199
A35: Jalisco's Restaurant | B35: Pre-Cancellation | C35: 618 Main St | D35: Watsonville | E35: CA | F35: 95076 | I35: 44364.697 | J35: Loza Delfina | M35: 60ccc8749adef3696bc9ab1a | N35: https://hub.spoton.com/merchants/60ccc8749adef3696bc9ab1a | T35: 545500001398189
A36: Jantz Cafe & Bakery | B36: In-Process | C36: 987 Bellevue Rd | D36: Atwater | E36: CA | F36: 95301 | I36: 44676.674 | J36: =- dale costa valley business machines -> #VALUE! | M36: 6268671324b4c415467be58b | N36: https://hub.spoton.com/merchants/6268671324b4c415467be58b | T36: 545500001580448
A37: Juice Joint Mexican Deli | B37: In-Process | C37: 332 Frank H Ogawa Plz | D37: Oakland | E37: CA | F37: 94612 | I37: 44606.694 | J37: Palacios Alvarez Jonathan | M37: 620af69124b4c472899427e1 | N37: https://hub.spoton.com/merchants/620af69124b4c472899427e1 | T37: 545500001537406
A38: Lefty's Grill | B38: Pre-Cancellation | C38: 101 Broad St | D38: Nevada City | E38: CA | F38: 95959 | I38: 44341.908 | J38: =- chris kado ck pos solutions -> #VALUE! | M38: 60ae9dbe9adef3d47d721b40 | N38: https://hub.spoton.com/merchants/60ae9dbe9adef3d47d721b40 | T38: 545500001384304
A39: Lefty's Taco House | B39: Pre-Cancellation | C39: 840 E Main St | D39: Grass Valley | E39: CA | F39: 95945 | I39: 44341.917 | J39: =- chris kado ck pos solutions -> #VALUE! | M39: 60ae9aec9adef3b2c4a2f1b5 | N39: https://hub.spoton.com/merchants/60ae9aec9adef3b2c4a2f1b5 | T39: 545500001384288
A40: Los Hermanos | B40: In-Process | C40: 2026 Chestnut St | D40: San Francisco | E40: CA | F40: 94123 | I40: 44559.548 | J40: Alden Rich | M40: 61ccea9e24b4c46d8acbc9c2 | N40: https://hub.spoton.com/merchants/61ccea9e24b4c46d8acbc9c2 | T40: 545500001512490
A41: Mamma Mia's | B41: In-Process | C41: 275 E Dunne Ave | D41: Morgan Hill | E41: CA | F41: 95037 | I41: 44645.6 | J41: LaBonte - Retail Chris | M41: 623e34d59adef3def6fe8dce | N41: https://hub.spoton.com/merchants/623e34d59adef3def6fe8dce | T41: 545500001560937
A42: Manor Grill | B42: In-Process | C42: 526 Manor Blvd | D42: San Leandro | E42: CA | F42: 94579 | I42: 44683.403 | J42: Lefour Alexandre | M42: 62705b5224b4c46662ee37e4 | N42: https://hub.spoton.com/merchants/62705b5224b4c46662ee37e4 | T42: 545500001584853
A43: Margarita's Bar & Grill | B43: In-Process | C43: 411 Vineyard Blvd | D43: Morgan Hill | E43: CA | F43: 95037 | I43: 44607.351 | J43: Valtierra Frank | M43: 620c2d0c24b4c447b52ad959 | N43: https://hub.spoton.com/merchants/620c2d0c24b4c447b52ad959 | T43: 545500001537943
A44: Mia | B44: In-Process | C44: 439 Water St | D44: Oakland | E44: CA | F44: 94607 | I44: 44595.698 | J44: Walker Stephen | M44: 61fd90b624b4c46b630090f0 | N44: https://hub.spoton.com/merchants/61fd90b624b4c46b630090f0 | T44: 545500001532365
...

Sheet Completed Installs
A1: Date | B1: Acct | C1: City | D1: Sell Date | E1: Status
A3: 44683 | B3: Seabreeze | C3: SF | D3: 44524 | E3: Installed
A4: 44684 | B4: Blind Pig | C4: SF | D4: 44593 | E4: Installed | G4: sent email
A5: 44684 | B5: Ocreanview Diner | C5: Berkeley | D5: 44636 | E5: Installed | G5: sent email
A6: 44687 | B6: El Burro Veloz | C6: Martinez | E6: Installed | G6: sent email
A7: 44690 | B7: Babette | C7: Berekeley | E7: Installed | G7: sent email
A8: 44690 | B8: Naan & Curry | C8: Pleasanton | D8: 44651 | E8: Installed | G8: sent email
A9: 44690 | B9: Juice Joint | C9: Oakland | D9: 44606 | E9: Installed | G9: sent email
A10: 44691 | B10: Asian Box- SFO | C10: SFO | E10: Installed | G10: sent email
A11: 44691 | B11: Ocean Grill | C11: Avila Beach | E11: Installed | G11: sent email
A13: 44693 | B13: Toast | C13: Novato | D13: 44897 | G13: sent email
A14: 44697 | B14: House of Prime Rib | C14: SF
A18: 44656 | B18: Craft Roots | C18: Morgan Hill | D18: 44895 | E18: Installed | G18: sent email
A19: 44657 | B19: The Vine & Spirits | C19: Danville | D19: 44630 | E19: Installed | G19: sent email
A20: 44662 | B20: Oasis Wine Lounge | C20: Pleasanton | D20: 44821 | E20: Installed | G20: happy with current supplier
