Workbook
Name ADDRESS: Master!#REF!
Name CC: Master!$M:$M
Name CD: Master!#REF!
Name CITY: Master!#REF!
Name CLIENT: Master!$A:$A
Name CONTACT_2: Master!$AD:$AD
Name COUNTY: Master!#REF!
Name EQUIP: Master!$B:$B
Name INSTALL: Master!#REF!
Name LICENSE: Master!#REF!
Name NAME: Master!$Q:$Q
Name PHONE: Master!$R:$R
Name PHONE_2: Master!$AE:$AE
Name REC: Master!#REF!
Name REM: Master!#REF!
Name STATE: Master!$Y:$Y
Name TERMS: Master!#REF!
Name VERS: Master!#REF!
Name ZIP: Master!$Z:$Z

Sheet New Client
B1: 0
J2: Invoice No:
C4: 100 Pelican Way, Suite "A" | J4: Date:
C5: San Rafael, Ca 94901 | J5: TERMS:
C6: 415-451-4861 | E6: Fax: 415-451-4866 | J6: Ordered by:
J7: Rep:
A8: ************************************************ | C8: ************************************ | F8: INVOICE | J8: *******************************
B10: Bill To | I10: Ship To:
B11: Client:
B12: c/o
B13: Address:
B14: City:
B16: Phone:
B17: Email:
C19: Products:
B20: Qty: | E20: Description: | J20: Unit Price | K20: Total
K21: =B21*J21 -> 0
K22: =B22*J22 -> 0
K23: =B23*J23 -> 0
K24: =B24*J24 -> 0
K25: =B25*J25 -> 0
K26: =B26*J26 -> 0
K27: =B27*J27 -> 0
I28: Taxable Subtotal: | K28: =SUM(K21:K27) -> 0
I29: Shipping & Handling:
I30: Sales Tax | J30: 0.09 | K30: =K28*J30 -> 0
C31: Services:
B32: Unit | E32: Description: | J32: Rate
K33: =B33*J33 -> 0
K34: =B34*J34 -> 0
K35: =B35*J35 -> 0
K36: =B36*J36 -> 0
K37: =B37*J37 -> 0
C39: Payment Details
J40: TOTAL: | K40: =SUM(K28:K39) -> 0
J42: office use only:
C46: I agree to the above charges and to pay this invoice according to the stated terms
C48: Client Signature
D50: This is your invoice. Kindly Pay from this invoice

Sheet Svc_Inv
J2: Invoice No:
C4: 100 Pelican Way, Suite "A" | J4: Date:
C5: San Rafael, Ca 94901 | J5: TERMS:
C6: 415-451-4861 | E6: Fax: 415-451-4866 | J6: Ordered by:
J7: Rep:
A8: ************************************************ | C8: ************************************ | F8: SERVICE INVOICE | J8: ***************************************
B10: Bill To | I10: Ship To:
B11: Client: | C11: Las Montanas Mkt - San Pablo | I11: =C11 -> Las Montanas Mkt - San Pablo
B12: c/o | C12: =LOOKUP(C11,Master!A:A,Master!AX:AX) | I12: =LOOKUP(C11,Master!A:A,Master!AW:AW)
B13: Address: | C13: =LOOKUP(C11,Master!A:A,Master!AY:AY) -> 13901 San Pablo Avenue | I13: =LOOKUP(C11,Master!A:A,Master!W:W) -> 13901 San Pablo Avenue
B14: City: | C14: =LOOKUP(C11,Master!A:A,Master!BA:BA) -> San Pablo | E14: =LOOKUP(C11,Master!A:A,Master!BB:BB) -> Ca | F14: =LOOKUP(C11,Master!A:A,Master!BC:BC) -> 94806 | I14: =LOOKUP(C11,Master!A:A,Master!X:X) -> San Pablo | J14: =LOOKUP(C11,Master!A:A,Master!Y:Y) -> Ca | K14: =LOOKUP(C11,Master!A:A,Master!Z:Z) -> 94806
B15: Phone: | C15: =LOOKUP(C11,Master!A:A,Master!BD:BD) -> 510-236-3397 | I15: =LOOKUP(C11,Master!A:A,Master!R:R) -> 510-236-3397
B16: Email: | C16: =LOOKUP(C11,Master!A:A,Master!#REF!) -> #REF!
B17: System | F17: Model# | J17: Serial#
B18: MICROS
B20: Problem As Reported:
B23: Work Performed
C26: Parts Billing:
B27: Qty: | E27: Description: | J27: Unit Price | K27: Total
K28: =B28*J28 -> 0
K29: =B29*J29 -> 0
K30: =B30*J30 -> 0
K31: =B31*J31 -> 0
K32: =B32*J32 -> 0
I33: Taxable Subtotal: | K33: =SUM(K28:K32) -> 0
B34: =LOOKUP(C11,Master!A:A,Master!C:C) -> LG | I34: Shipping & Handling:
B35: =LOOKUP(C11,Master!A:A,Master!V:V) -> San Pab | I35: Sales Tax | J35: =LOOKUP(C11,Master!A:A,Master!T:T) -> 0.0875 | K35: =J35*K33 -> 0
C36: Labor Billing:
E37: Description:
K38: =SUM(B38*J38) -> 0
K39: =SUM(B39*J39) -> 0
K40: =SUM(B40*J40) -> 0
K41: =SUM(B41*J41) -> 0
I42: Travel
C44: Payment Details
J45: TOTAL: | K45: =SUM(K33:K42) -> 0
J47: office use only:
C51: I agree to the above charges and to pay this invoice according to the stated terms
C54: Client Signature
D56: This is your invoice. Kindly Pay from this invoice

Sheet Prod_Inv
J2: Invoice No: | K2: 09150105
C4: 100 Pelican Way, Suite "A" | J4: Date: | K4: 44089
C5: San Rafael, Ca 94901 | J5: TERMS: | K5: Net 30
C6: 415-451-4861 | E6: Fax: 415-451-4866 | J6: Ordered by: | K6: Garret
J7: Rep: | K7: Antonio
A8: ************************************************ | C8: ************************************ | F8: INVOICE | J8: *******************************
B10: Bill To | I10: Deliver To
B11: Client: | C11: Layla at MacAthur Place | I11: =C11 -> Layla at MacAthur Place
B12: c/o
B13: Address: | C13: =LOOKUP(C11,Master!A:A,Master!AY:AY) -> 29 E MacArthur Street | I13: =LOOKUP(C11,Master!A:A,Master!W:W) -> 29 E MacArthur Street
B14: City: | C14: =LOOKUP(C11,Master!A:A,Master!BA:BA) -> Sonoma | E14: =LOOKUP(C11,Master!A:A,Master!BB:BB) -> Ca | F14: =LOOKUP(C11,Master!A:A,Master!BC:BC) -> 95476 | I14: =LOOKUP(C11,Master!A:A,Master!X:X) -> Sonoma | J14: =LOOKUP(C11,Master!A:A,Master!Y:Y) -> Ca | K14: =LOOKUP(C11,Master!A:A,Master!Z:Z) -> 95476
B15: Phone: | C15: =LOOKUP(C11,Master!A:A,Master!BD:BD) -> 707-933-3191 | I15: =LOOKUP(C11,Master!A:A,Master!R:R) -> 707-933-3191
B16: Email:
C18: Products:
B19: Qty: | E19: Description: | J19: Unit Price | K19: Total
K20: =B20*J20 -> 0
B21: 2 | C21: # CC-235 | D21: Epson Impact | F21: 3" two ply x 95' | I21: 50 rolls | J21: 45 | K21: =B21*J21 -> 90
K22: =B22*J22 -> 0
K23: =B23*J23 -> 0
K24: =B24*J24 -> 0
K25: =B25*J25 -> 0
K26: =B26*J26 -> 0
K27: =B27*J27 -> 0
B28: =LOOKUP(C11,Master!A:A,Master!C:C) -> AH | I28: Taxable Subtotal: | K28: =SUM(K20:K27) -> 90
B29: =LOOKUP(C11,Master!A:A,Master!V:V) -> SON | I29: Shipping
I30: Sales Tax | J30: =LOOKUP(C11,Master!A:A,Master!T:T) -> 0.0825 | K30: =K28*J30 -> 7.425
C31: Services:
B32: Unit | E32: Description: | J32: Rate
K33: =B33*J33 -> 0
K34: =B34*J34 -> 0
K35: =B35*J35 -> 0
K36: =SUM(B36*J36) -> 0
K37: =SUM(B37*J37) -> 0
K38: =B38*J38 -> 0
I39: Travel
C41: Payment Details
J42: TOTAL: | K42: =SUM(K28:K39) -> 97.425
J44: office use only:
C48: I agree to the above charges and to pay this invoice according to the stated terms
C50: Client Signature
...

Sheet Master
A1: 44088 | B1: SYSTEM | E1: CORONA STATUS | F1: HELP DESK | I1: HARDWARE MAINT | L1: REVENUE TRACKING | Q1: PRIMARY CONTACT | T1: TAX% | U1: Tax % | V1: Tax Dist | W1: STORE ADDRESS | AA1: Ops Email | AB1: Billing Email | AC1: Other Email | AD1: CONTACT #2 | AF1: CONTACT #3 | AH1: CONTACT #4 | AJ1: CONTACT #5 | AL1: FAX | AN1: website | AO1: Paper #1 | AP1: Paper #2 | AQ1: Paper #3 | AR1: Ribbon #1 | AS1: Ribbon #2 | AT1: Label/Other | AU1: Other | AV1: freight ? | AX1: Bill To Name | AY1: Street | BA1: City | BB1: St | BC1: Zip | BD1: Phone | BF1: License # | BG1: Version | BH1: # Terms | BI1: WS | BJ1: RECEIPT | BK1: CD | BL1: REMOTE | BM1: SCANNER | BN1: SCALE | BO1: ROUTER | BP1: SWITCH | BQ1: TRAN / EPAY | BR1: TRAN VERSION | BS1: EMV DEVICE | BT1: FILE SERVER | BU1: OP SYS | BV1: HW OTHER | BW1: HW OTHER | BX1: HW OTHER | BY1: HW OTHER | BZ1: SW OTHER | CA1: SW OTHER | CB1: ***NOTES***
B2: type | C2: AM | D2: WS | F2: y/n ? | G2: exp | H2: $$ | I2: y/n ? | J2: exp | K2: $$ | L2: LAST SUPPLY?? | M2: MERCHANT | N2: RHQ? | O2: ONLINE ? | P2: LAST T&M ?? | Q2: Name | R2: Phone | S2: Cell | T2: 2017 | W2: STREET | X2: CITY | Y2: ST | Z2: ZIP | AD2: Name | AE2: Phone | AF2: Name | AG2: Phone | AH2: Name | AI2: Phone | AJ2: Name | AK2: Phone | AL2: Store | AM2: Corp or A/P | AO2: Supply Info | AX2: Billing Info | BF2: Hardware/Software Detail
A3: 19 Broadway | B3: SUPPLY ONLY | C3: DK | F3: NO | I3: NO | L3: 43208 | Q3: Garry Graham | R3: 415-459-1091 | S3: 415-459-0293 | T3: 0.09 | U3: 0.09 | V3: Fairfax | W3: 17 Broadway | X3: Fairfax | Y3: Ca | Z3: 94930 | AO3: 54220 $49 | AV3: YES | AY3: 17 Broadway | BA3: Fairfax | BB3: Ca | BC3: 94930 | BD3: 415-459-1091
A4: 2 Star Market | B4: Casio QT 6600 | C4: LG | F4: NO | I4: NO | P4: 43927 | Q4: Ali | R4: 510-531-3576 | T4: 0.0975 | V4: ALA | W4: 2020 MacArthur Blvd | X4: Oakland | Y4: Ca | Z4: 94602 | AY4: 2020 MacArthur Blvd | BA4: Oakland | BB4: Ca | BC4: 94602 | BD4: 510-531-3576
A5: 26 Mix | B5: ECR | C5: AH | D5: Sam4s ER945 raised | F5: NO | I5: NO | L5: 43355 | P5: 43355 | Q5: William Mayorga | R5: 415-826-7378 | S5: 510-734-5931 | T5: 0.085 | U5: 0.0875 | V5: SF | W5: 3024 Mission Street | X5: San Francisco | Y5: Ca | Z5: 94110 | AY5: 3024 Mission Street | BA5: San Francisco | BB5: Ca | BC5: 94110 | BD5: 415-826-7378 | BH5: 2 | BI5: Sam4s 945 raised
A6: 3 Star Food & Liquor | B6: CASIO | C6: LG | D6: Casio TE7000 | F6: NO | I6: NO | P6: 43026 | Q6: Mandeep | R6: 510-340-1366 | T6: 0.0875 | U6: 0.085 | V6: Concord | W6: 1140 Meadow Lane | X6: Concord | Y6: Ca | Z6: 94520 | AD6: Dependu | AY6: 1140 Meadow Lane | BA6: Concord | BB6: Ca | BC6: 94520 | BD6: 510-340-1366 | BH6: 1 | BI6: TE7000 | BK6: DL3616
A7: 420 Smoke Palace | B7: ECR | C7: AH | D7: Sam4s SAP-630RT | F7: NO | I7: NO | L7: 43878 | P7: 43878 | Q7: Abassi | R7: 408-880-4200 | T7: 0.0925 | V7: SC | W7: 396 S. Bascom Avenue | X7: San Jose | Y7: Ca | Z7: 95128 | AO7: 54220 $57 | AV7: NO | AY7: 396 S. Bacom Avenue | BA7: San Jose | BB7: Ca | BC7: 95128 | BD7: 408-880-4200
A8: 5 Star Enterprises | B8: ECR | C8: AH | D8: Sam4s ER285 | F8: NO | I8: NO | L8: 42691 | Q8: Phil | R8: 707-391-6581 | T8: 0.08875 | U8: 0.08125 | V8: Ukiah | W8: 595 North State Street | X8: Ukiah | Y8: Ca | Z8: 95482 | AA8: fivestarphil21@yahoo.com | AY8: 595 North State Street | BA8: Ukiah | BB8: Ca | BC8: 95482 | BD8: 707-391-6581
A9: 5th Street Steakhouse | B9: SUPPLY ONLY | C9: AH | F9: NO | I9: NO | L9: 44011 | Q9: Traci | R9: 530-891-6328 | T9: 0.0725 | U9: 0.075 | V9: BUTTE | W9: 345 W. 5th Street | X9: Chico | Y9: Ca | Z9: 95928 | AA9: wearschico@yahoo.com | AB9: wearschico@yahoo.com | AD9: Angela | AL9: 530-891-8339 | AO9: 54220 $55 | AP9: 13305 $31 | AQ9: CC235 $45 | AR9: 62245 $39 | AS9: 62235 $39 | AV9: NO | AY9: 345 W. 5th Street | BA9: Chico | BB9: Ca | BC9: 95928 | BD9: 530-891-6328
A10: 6 To Late Food & Liquor | B10: CASIO. | C10: LG | D10: Casio TE7000 | F10: NO | I10: NO | L10: 42881 | P10: 43172 | Q10: Ramesh | R10: 510-789-9537 | T10: 0.0925 | U10: 0.09 | V10: SanJose | W10: 5138 Monterey Hwy, Suite D | X10: San Jose | Y10: Ca | Z10: 95111 | AO10: 15157 $46.55 | AV10: NO | AY10: =W10 -> 5138 Monterey Hwy, Suite D | BA10: San Jose | BB10: =Y10 -> Ca | BC10: =Z10 -> 95111 | BD10: =R10 -> 510-789-9537 | BH10: 1 | BI10: TE7000 | BJ10: inc | BK10: DL3616 | BL10: none | BM10: Orbit 232 | BN10: none | BO10: none | BP10: none | BQ10: none | BT10: none | BU10: none
A11: 7 Mile House | B11: SUPPLY ONLY | C11: AH | F11: NO | I11: NO | Q11: Lory Marquez | R11: 415-467-2343 | T11: 0.0875 | U11: 0.09 | V11: SM | W11: 2800 Bayshore Blvd | X11: Brisbane | Y11: Ca | Z11: 94005 | AA11: lvgloriani@yahoo.com | AD11: Lory A/P | AE11: 415-269-5452 | AF11: Vanessa (owner) | AY11: 2800 Bayshore Blvd | BA11: Brisbane | BB11: Ca | BC11: 94005 | BD11: 415-467-2343
A12: 76 Auto Care Service | B12: SUPPLY ONLY | C12: AH | F12: NO | I12: NO | L12: 43544 | Q12: Babu | R12: 510-530-5605 | T12: 0.0925 | V12: ALA | W12: 4500 Park Blvd | X12: Oakland | Y12: Ca | Z12: 94602 | AO12: 54220 $55 | AP12: 15153 $49 | AV12: YES | AY12: 4500 Park Blvd | BA12: Oakland | BB12: Ca | BC12: 94602 | BD12: 510-530-5605
A13: 9th Street Café | B13: SUPPLY ONLY | C13: AH | F13: NO | I13: NO | L13: 43243 | M13: WORLDPAY | P13: 43038 | Q13: Ala | R13: 510-845-4852 | T13: 0.0925 | U13: 0.095 | V13: ALA | W13: 2570 9th Street | X13: Berkeley | Y13: Ca | Z13: 94710 | AL13: 510-549-2522 | AO13: 54220 $57 | AP13: 13305 $31 | AV13: NO | AY13: =PROPER(AZ13) -> 2570 9Th Street | AZ13: 2570 9TH STREET | BA13: Berkeley | BB13: Ca | BC13: 94710 | BD13: 510-845-4852 | BH13: 3 | CB13: Formerly Westside Bakery FYI
A14: a Mano | B14: ALOHA | C14: RF | F14: 7x24 | G14: 44089 | H14: 300 | I14: NO | L14: 44082 | P14: 44057 | Q14: Rodrigo | R14: 415-506-7401 | S14: 415-271-3947 | T14: 0.085 | V14: SF | W14: 450 Hayes Street | X14: San Francisco | Y14: Ca | Z14: 94102 | AA14: info@amanosf.com | AB14: iberdougo@backofthehouseinc.com | AC14: rodrigo@backofthehouseinc.com | AL14: 415-506-7401 | AO14: 54220 $54 | AP14: 13305 $34 | AQ14: CC235 $44 | AR14: 62245 $34 | AV14: YES | AY14: 450 Hayes St | BA14: San Francisco | BB14: Ca | BC14: 94102 | BD14: 415-881-7020 | BK14: MS-460 | CB14: Email all future invocies to email on file (info one)
A15: A Sweet Affair - California | B15: NCC | C15: DF | D15: Spt4500 | F15: NO | I15: NO | P15: 43859 | Q15: Terry | R15: 925-943-2253 | S15: 925-785-5931 | T15: 0.0825 | U15: 0.085 | V15: CC | W15: 1991 N California Blvd | X15: Walnut Creek | Y15: Ca | Z15: 94598 | AA15: asweetaffairbakery@usa.com | AB15: idreamofaruba@gmail.com | AD15: Sarah Torres -> | AE15: 925-395-1695 | AF15: EMAIL IDREAM | AY15: 1991 N California Blvd | BA15: Walnut Creek | BB15: Ca | BC15: 94598 | BD15: 925-785-5931 | BH15: 2
A16: A Sweet Affair - Ygnacio | B16: NCC | C16: AF | D16: Acrobat | F16: NO | I16: NO | M16: WORLDPAY | P16: 43206 | Q16: Jennifer | R16: 925-944-1910 | T16: 0.0825 | U16: 0.085 | V16: CC | W16: 1815F Ygnacio Valley Road | X16: Walnut Creek | Y16: Ca | Z16: 94598 | AA16: bakerhot1@aol.com | AD16: Terry-owner | AE16: 925-785-5931 | AL16: 925-947-6000 | AY16: 1815 Ygnacio Valley Road #F | BA16: Walnut Creek | BB16: Ca | BC16: 94598 | BD16: 925-944-1910 | BH16: 5
A17: A&W - San Rafael | B17: BRINK | C17: DK | F17: M-F | G17: 44089 | H17: 49 | I17: DEPOT | J17: 44089 | K17: 108 | L17: 43747 | P17: 43887 | Q17: Mark/David | R17: 415-479-9652 | S17: D.415-450-8300 | T17: 0.09 | V17: SR | W17: 3741 Redwood Highway | X17: San Rafael | Y17: Ca | Z17: 94903 | AA17: bigbromberger@gmail.com | AB17: brombergerville@hotmail.com | AO17: 15303 $35 | AV17: PICKUP | AY17: 3741 Redwood Highway | BA17: San Rafael | BB17: Ca | BC17: 94903 | BD17: 415-479-9652
A18: Abe's Liquor & Market | B18: CASIO | C18: LG | D18: Casio TE7000 | F18: NO | I18: NO | Q18: Rafique | R18: 415-552-4245 | T18: 0.0925 | U18: 0.09 | V18: SanJose | W18: 1939 Alum Rock Avenue | X18: San Jose | Y18: Ca | Z18: 95116 | AY18: 1939 Alum Rock Avenue | BA18: San Jose | BB18: Ca | BC18: 95116 | BD18: 415-552-4245
A19: AC Liquor and Food Mart | B19: CASIO | C19: LG | D19: Casio TE7000 | F19: NO | I19: NO | Q19: Manager | R19: 707-561-0115 | T19: 0.0775 | U19: 0.08 | V19: NAPA | W19: 3915 Broadway Street | X19: AmerIcan Canyon | Y19: Ca | Z19: 94503 | AY19: 3915 Broadway Street | BA19: AmerIcan Canyon | BB19: Ca | BC19: 94503 | BD19: 707-561-0115
A20: Ace Wasabi | B20: MAITRE'D | C20: JS | F20: M-F | G20: 44412 | H20: 500 | I20: NO | L20: 44054 | Q20: Ken Lowe | R20: 415-567-4903 | S20: 415-819-8477 | T20: 0.085 | U20: 0.0875 | V20: SF | W20: 3339 Steiner Street | X20: San Francisco | Y20: Ca | Z20: 94123 | AA20: klowe1414@yahoo.com | AB20: klowe1234@gmail.com | AD20: vicas | AE20: 415-850-7530 | AL20: 415-749-1873 | AO20: 54220 $56 | AP20: 13305 $31 | AR20: 62245 $39 | AV20: NO | AY20: 3339 Steiner Street | AZ20: 3339 STEINER STREET | BA20: San Francisco | BB20: Ca | BC20: 94123 | BD20: 415-576-4903 | BF20: 1007764 | BG20: 7.05.065.003 | BH20: 2
A21: Ada Café | B21: ECR | C21: AH | D21: TEC ma600 | F21: NO | I21: NO | P21: 42977 | Q21: Dat | R21: 510-225-7062 | T21: 0.0925 | V21: ALA | W21: 3075 Adeline Street | X21: Berkeley | Y21: Ca | Z21: 94703 | AY21: 3075 Adeline Street | BA21: Berkeley | BB21: Ca | BC21: 94703 | BD21: 510-225-7062 | BH21: 1 | BI21: TEC ma600
A22: Adam's Restaurant (CLOSED) | B22: NCC | C22: AF | F22: NO | I22: NO | L22: 43089 | P22: 43213 | Q22: Adam | R22: 707-456-9226 | T22: 0.08375 | U22: 0.08125 | V22: Willit | W22: 50 South Main Street | X22: Willits | Y22: Ca | Z22: 95490 | AA22: defchefcater@hotmail.com | AR22: 62245 $39 | AV22: YES | AY22: 50 South Main Street | BA22: Willits | BB22: Ca | BC22: 95490 | BD22: 707-456-9226 | BH22: 1
A23: Adobe Road Winery | B23: SUPPLY ONLY | C23: AH | F23: NO | I23: NO | L23: 42781 | Q23: Larry | R23: 650-464-9502 | T23: 0.0825 | V23: SON | W23: 6 Petaluma Blvd N. Ste A1 | X23: Petaluma | Y23: Ca | Z23: 94954 | AU23: cleaner $7.50 | AV23: YES | AY23: 6 Petaluma Blvd N. Ste A1 | BA23: Petaluma | BB23: Ca | BC23: 94954 | BD23: 650-464-9502
A24: Akane Japanese Cuisine | B24: SUPPLY ONLY | C24: AH | F24: NO | I24: NO | L24: 43329 | Q24: Frances | R24: 650-941-8150 | T24: 0.09 | U24: 0.0875 | V24: SC | W24: 250 Third Street | X24: Los Altos | Y24: Ca | Z24: 94022 | AL24: 650-941-3007 | AO24: 46175 $75 | AV24: YES | AY24: 250 Third Street | BA24: Los Altos | BB24: Ca | BC24: 94022 | BD24: 650-941-8150
A25: Alameda Cellars | B25: ECR | C25: AH | D25: Sam4s SPS2000 | F25: NO | I25: NO | Q25: Matt | R25: 510-521-3100 | T25: 0.0975 | U25: 0.095 | V25: Alam | W25: 2425 Encinal Avenue | X25: Alameda | Y25: Ca | Z25: 94501 | AY25: 2425 Encinal Avenue | BA25: Alameda | BB25: Ca | BC25: 94501 | BD25: 510-521-3100 | BH25: 2
A26: Alana's - Burlingame | B26: NCC | C26: AF | F26: 7x24 | G26: 44105 | H26: 49 | I26: M-F | J26: 44105 | K26: 39 | L26: 42843 | M26: WORLDPAY | N26: RHQ | P26: 44077 | Q26: Francesca | R26: 650-348-0417 | S26: 650-799-9230 | T26: 0.09 | U26: 0.09 | V26: Burl | W26: 1408 Burlingame Avenue | X26: Burlingame | Y26: Ca | Z26: 94010 | AA26: info@alanascafe.com | AB26: francesca@alanascafe.com | AD26: Teresa | AF26: Tim | AG26: 650-703-9981 | AO26: 54220 $47 | AQ26: CC235 $37 | AR26: 62245 $29 | AV26: YES | AY26: =PROPER(AZ26) -> 1408 Burlingame Avenue | AZ26: 1408 BURLINGAME AVENUE | BA26: Burlingame | BB26: Ca | BC26: 94010 | BD26: 650-348-0417 | BH26: 2
A27: Alana's - Redwood City | B27: NCC | C27: AF | E27: CLOSED | F27: NO | I27: NO | M27: WORLDPAY | N27: RHQ | P27: 43552 | Q27: Teresa | R27: 650-366-1498 | S27: 650-799-9210 | T27: 0.0925 | U27: 0.09 | V27: Redwood | W27: 1020 Main Street | X27: Redwood City | Y27: Ca | Z27: 94063 | AA27: info@alanascafe.com | AB27: teresa@alanascafe.com | AD27: Francesca | AF27: Tim | AG27: 650-703-9981 | AL27: 650-366-2117 | AY27: =PROPER(AZ27) -> 1020 Main Street | AZ27: 1020 MAIN STREET | BA27: Redwood City | BB27: Ca | BC27: 94063 | BD27: 650-366-1498
A28: Alberto's Mexican Food - Oak Hills | B28: MAITRE'D | C28: JS | F28: 7 X 24 | G28: 44234 | H28: 900 | I28: NO | L28: 42835 | M28: WORLDPAY | P28: 43842 | Q28: Gerardo Navarro | R28: 760-244-0026 | S28: 909-379-2951 | T28: 0.0775 | U28: 0.0825 | V28: S.BERN | W28: 13374 Ranchero Road | X28: Oak Hills | Y28: Ca | Z28: 92344 | AF28: Sean (outside help) | AG28: 951-823-9428 | AO28: 54220 $49 | AV28: YES | AY28: 13374 Ranchero Road | BA28: Oak Hills | BB28: Ca | BC28: 92344 | BD28: 909-882-5667 | BF28: 1409705 | BG28: 7.04.032.005 | BH28: 3 | BK28: MS 460-epson | BV28: Oneac UPS
A29: Alberto's Mexican Food - San Bern | B29: MAITRE'D | C29: JS | D29: PT SP800 | F29: 7 X 24 | G29: 44126 | H29: 900 | I29: NO | M29: WORLDPAY | P29: 44019 | Q29: Hector Navarro | R29: 909-882-5667 | S29: 909-379-2720 | T29: 0.08 | U29: 0.0825 | V29: San Bern | W29: 1008 West Highland | X29: San Bernadino | Y29: Ca | Z29: 92405 | AA29: jesdanger@aol.com | AY29: 1008 West Highland | BA29: San Bernadino | BB29: Ca | BC29: 92405 | BD29: 909-822-5667 | BF29: 1413933 | BH29: 3 | BI29: SP800
A30: Alegria's | B30: SUPPLY ONLY | C30: AH | F30: NO | I30: NO | L30: 43077 | P30: 43668 | Q30: Angelynne | R30: 415-929-8888 | T30: 0.085 | U30: 0.0875 | V30: SF | W30: 2018 Lombard Street | X30: San Francisco | Y30: Ca | Z30: 94123 | AA30: info@alegraissf.com | AD30: Arman | AP30: CC235 $39 | AR30: 62245 $39 | AV30: NO | AY30: =PROPER(AZ30) -> 2018 Lombard Street | AZ30: 2018 LOMBARD STREET | BA30: San Francisco | BB30: Ca | BC30: 94123 | BD30: 415-929-8888 | BH30: 2
A31: Alejandro's Taqueria - Fairfield | B31: ECR | C31: AH | D31: Sam ER940 flat | F31: NO | I31: NO | L31: 43906 | P31: 42929 | Q31: Lety | R31: 707-429-2155 | T31: 0.08375 | V31: SOL | W31: 936 Texas Street | X31: Fairfield | Y31: Ca | Z31: 94533 | AO31: 15157 $49 | AP31: 44150 $27 | AR31: 67655 $39 | AV31: YES | AY31: 936 Texas Street | BA31: Fairfield | BB31: Ca | BC31: 94533 | BD31: 707-429-2155
A32: Alejandro's Taqueria - Sacramento | B32: ECR | C32: AH | D32: Sam ER940 flat | F32: NO | I32: NO | P32: 43581 | Q32: Luis | R32: 916-459-0924 | T32: 0.0875 | V32: Sacmen | W32: 911 K Street | X32: Sacramento | Y32: Ca | Z32: 95814 | AA32: lbarr@sbcglobal.net | AC32: lbarr@sbcglobal.net | AO32: 15157 $49 | AV32: YES | AY32: 911 K Street | BA32: Sacramento | BB32: Ca | BC32: 95814 | BD32: 916-459-0924 | BH32: 2 | BI32: 1450/Sam4s ER940
A33: Alejandro's Taqueria - Vacaville | B33: ECR | C33: AH | D33: TEC FS1450 | F33: NO | I33: NO | Q33: Javier | R33: 707-448-8899 | T33: 0.08125 | U33: 0.07875 | V33: Vaca | W33: 348 Merchant Street | X33: Vacaville | Y33: Ca | Z33: 94568 | AD33: ALEJANDRO | AL33: 707-448-8899 | AY33: =PROPER(AZ33) -> 348 Merchant Street | AZ33: 348 MERCHANT STREET | BA33: Vacaville | BB33: Ca | BC33: 94568 | BD33: 707-448-8899 | BH33: 1
A34: Alexanders Steakhouse | B34: SUPPLY ONLY | C34: AH | F34: NO | I34: NO | Q34: Manager | R34: 408-446-2222 | T34: 0.09 | U34: 0.0875 | V34: Cuper | W34: 10330 N. Wolfe Road | X34: Cupertino | Y34: Ca | Z34: 95014 | AA34: CHEFSTOUT@ALEXANDERSSTEAKHOUSE.COM | AB34: accounting@alexandersteakhouse.com | AD34: Jeff Stout | AE34: 510-589-7077 | AF34: erin | AH34: Tim | AL34: 408-446-2242 | AY34: =PROPER(AZ34) -> 10330 N. Wolfe Road | AZ34: 10330 N. WOLFE ROAD | BA34: Cupertino | BB34: Ca | BC34: 95014 | BD34: 408-446-2222 | BH34: 7
A35: Alioto's | B35: SQUIRREL | C35: RF | F35: NO | I35: NO | P35: 43882 | Q35: Steven Fine | R35: 415-673-8300 | S35: Ext 1300 | T35: 0.085 | U35: 0.0875 | V35: SF | W35: 360A Jefferson Street | X35: San Francisco | Y35: Ca | Z35: 94113 | AA35: deesf888@yahoo.com | AB35: francesca@aliotos.com | AC35: steven@aliotos.com | AL35: 415-931-6792 | AN35: www.aliotos.com | AY35: 360A Jefferson Street | BA35: San Francisco | BB35: Ca | BC35: 94113 | BD35: 415-673-8300 | BH35: 1
A36: All Star Donut | B36: ECR | C36: AH | D36: SAM 260 | F36: NO | I36: NO | P36: 43756 | Q36: Sem | R36: 510-525-7289 | T36: 0.0925 | U36: 0.095 | V36: El Cerr | W36: 3070 El Cerrito Plaza | X36: El Cerrito | Y36: Ca | Z36: 94530 | AY36: 3070 El Cerrito Plaza | BA36: El Cerrito | BB36: Ca | BC36: 94530 | BD36: 510-525-7289
A37: Alma de la Rosa Restaurant | B37: SUPPLY ONLY | C37: AH | F37: NO | I37: NO | L37: 42990 | Q37: Max | R37: 626-564-8111 | T37: 0.1025 | U37: 0.09 | V37: Pasa | W37: 41 Hugus Alley | X37: Pasadena | Y37: Ca | Z37: 91103 | AD37: Max | AF37: Michael Moore | AH37: Noelle | AO37: 54220 $49 | AP37: 13305 $27 | AQ37: CC235 $37 | AR37: 62245 $25 | AV37: YES | AY37: 41 Hugus Alley | BA37: Pasadena | BB37: Ca | BC37: 91103 | BD37: 626-564-8111
A38: Alotta's Deli | B38: SUPPLY ONLY | C38: RA | F38: NO | I38: NO | P38: 43888 | Q38: Mike | R38: 650-967-0299 | S38: 408-807-0575 | T38: 0.085 | V38: SC | W38: 2249 Grant Road | X38: Los Altos | Y38: Ca | Z38: 94024 | AY38: 2249 Grant Road | BA38: Los Altos | BB38: Ca | BC38: 94024 | BD38: 650-967-0299
A39: Al's Liquor | B39: ECR | C39: AH | D39: Sam4s SPS520 | F39: NO | I39: NO | P39: 43049 | Q39: Jas | R39: 650-583-8920 | S39: 718-866-8232 | T39: 0.0925 | U39: 0.0875 | V39: So.Sf | W39: 479 Grand Avenue | X39: South San Francisco | Y39: Ca | Z39: 94080 | AY39: 479 Grand Avenue | BA39: South San Francisco | BB39: Ca | BC39: 94080 | BD39: 650-583-8920 | BI39: SPS520
A40: Amakara | B40: SUPPLY ONLY | C40: AH | F40: NO | I40: NO | L40: 43829 | P40: 43032 | Q40: Myly | R40: 925-803-8485 | S40: 925-992-9819 | T40: 0.0925 | U40: 0.095 | V40: ALA | W40: 7222 Regional Street | X40: Dublin | Y40: Ca | Z40: 94568 | AA40: amakaracompany@gmail.com | AD40: Eddie (owner) | AE40: 209-601-8923 | AF40: Tae Oh | AG40: 408-981-6142 | AO40: 54273 $65 | AP40: 13305 $34 | AQ40: CC235 $45 | AR40: 62245 $35 | AV40: NO | AY40: =PROPER(AZ40) -> 7222 Regional Street | AZ40: 7222 REGIONAL STREET | BA40: Dublin | BB40: Ca | BC40: 94568 | BD40: 925-803-8485 | BF40: 1410096 | BG40: 2005 | BH40: 3 | BQ40: ePay FDMS Nashville
...

Sheet SUPPLY ITEMS
C1: SUPPLY ITEMS
A4: Note: | B4: All prices are for pickup. Please add shipping fees below when using FEDEX
B5: Contact Supply dept for customized/discounted pricing schedule based on volume annual purchases
A8: MOST COMMON | D8: All prices are for pickup. Please add shipping fees below
B10: 1 | C10: # 54-220 | D10: Epson Thermal | F10: 3 1/8 x 220' | I10: 50 rolls | J10: 49 | K10: =B10*J10 -> 49
B11: 1 | C11: # 13-305 | D11: Epson Impact | F11: 3" one ply x 165 | I11: 50 rolls | J11: 29 | K11: =B11*J11 -> 29
B12: 1 | C12: # 62245 | D12: Epson 220 Ink | F12: black/red ribbons | I12: Per Dozen | J12: 39 | K12: =B12*J12 -> 39
B14: 1 | C14: # CC-235 | D14: Epson Impact | F14: 3" two ply x 95' | I14: 50 rolls | J14: 39 | K14: =B14*J14 -> 39
B16: 1 | C16: # 15-157 | D16: Cash Reg- Thermal | F16: 2.25" x 230 feet | I16: 50 rolls | J16: 49 | K16: =B16*J16 -> 49
B17: 1 | C17: # 44-150 | D17: Cash Reg- Impact | F17: 44mm x 150 ft | I17: 80 rolls | J17: 25 | K17: =B17*J17 -> 25
B19: 1 | C19: # 15-740 | D19: CC Machine | F19: 2.25" x 70 feet | I19: 100 rolls | J19: 49 | K19: =B19*J19 -> 49
B20: 1 | C20: # 15-745 | D20: CC Machine | F20: 2.25" x 70 feet | I20: 50 rolls | J20: 29 | K20: =B20*J20 -> 29
B21: 1 | C21: # 15-185 | D21: CC Machine | F21: 2 1/4 x 85' thermal | I21: 50 rolls | J21: 35 | K21: =B21*J21 -> 35
B23: 1 | C23: # 46-175 | D23: Epson Thermal | F23: 3 1/8" heavy duty | I23: 50 rolls | J23: 69 | K23: =B23*J23 -> 69
B24: 1 | C24: # 54-273 | D24: Epson Thermal | F24: 3 1/8 x 273'- xlong | I24: 50 rolls | J24: 69 | K24: =B24*J24 -> 69
B26: 1 | C26: # 62235 | D26: Epson 220 Ink | F26: black ribbons | I26: Per Dozen | J26: 39 | K26: =B26*J26 -> 39
B27: 1 | C27: # 67240 | D27: STAR SP700/712 | F27: black/red ribbons | I27: Per Dozen | J27: 39 | K27: =B27*J27 -> 39
A30: PAPER | D30: All prices are for pickup. Please add shipping fees below
B31: 1 | C31: # 12-100 | D31: one ply paper | F31: 2 1/4" x 150 feet | I31: 100 rolls | J31: 49 | K31: =B31*J31 -> 49
B32: 1 | C32: # 13-304 | D32: one ply paper | F32: 2 3/4" x 165 feet | I32: 50 rolls | J32: 29 | K32: =B32*J32 -> 29
B33: 1 | C33: # 13-305C | D33: one ply paper | F33: 3" one ply canary | I33: 50 rolls | J33: 49 | K33: =B33*J33 -> 49
B34: 1 | C34: # 13-305G | D34: one ply paper | F34: 3" one ply green | I34: 50 rolls | J34: 49 | K34: =B34*J34 -> 49
B35: 1 | C35: # 13-450 | D35: one ply paper | F35: 4 1/2" x 165 feet | I35: 50 rolls | J35: 52.5 | K35: =B35*J35 -> 52.5
B36: 1 | C36: # 15-044 | D36: thermal paper | F36: 44mm x 230 feet | I36: 50 rolls | J36: 39 | K36: =B36*J36 -> 39
B37: 1 | C37: # 15-157 | D37: 2 1/4 x 230'thermal | F37: Cash Reg- Thermal | I37: 50 rolls | J37: 49 | K37: =B37*J37 -> 49
B38: 1 | C38: # 15-160 | D38: 2 1/4 x 60' thermal | F38: Verifone Thermal | I38: 50 rolls | J38: 29 | K38: =B38*J38 -> 29
B39: 1 | C39: # 15-185 | D39: 2 1/4 x 85' thermal | F39: Verifone Thermal | I39: 50 rolls | J39: 35 | K39: =B39*J39 -> 35
B40: 1 | C40: # 15-303 | D40: thermal paper | F40: 2.25" x 42 feet | I40: 48 rolls | J40: 29 | K40: =B40*J40 -> 29
B41: 1 | C41: # 15-740 | D41: CC Machine | F41: 2.25" x 70 feet | I41: 100 rolls | J41: 49 | K41: =B41*J41 -> 49
B42: 1 | C42: # 15-745 | D42: CC Machine | F42: 2.25" x 70 feet | I42: 50 rolls | J42: 29 | K42: =B42*J42 -> 29
... B63: 1 | C63: # CC-235 | D63: 3" TWO ply | F63: Epson TMU-220 | I63: 50 rolls | J63: 39 | K63: =B63*J63 -> 39
B65: 1 | C65: # 80340 | D65: Std Printer paper, 8 1/2 x 11", 500 sheet | I65: ea | J65: 10 | K65: =B65*J65 -> 10
B66: 1 | C66: # 80342 | D66: Legal Size Printer paper, 8 1/2 x 14", 500 sheet | I66: ea | J66: 12.5 | K66: =B66*J66 -> 12.5
B67: 1 | C67: # 85000 | D67: Colored Menu Paper | F67: 500 sheet | I67: ea | J67: 19.5 | K67: =B67*J67 -> 19.5
A70: RIBBONS | D70: All prices are for pickup. Please add shipping fees below
B71: 1 | C71: # 68915 | D71: purple ribbons | F71: Victor 600 | I71: Per Dozen | J71: 39 | K71: =B71*J71 -> 39
B72: 1 | C72: # 68905 | D72: black/red ribbons | F72: Victor 600 | I72: Per Dozen | J72: 39 | K72: =B72*J72 -> 39
B73: 1 | C73: # 68715 | D73: purple/red ribbons | F73: Veriphone 900 | I73: Per Dozen | J73: 39 | K73: =B73*J73 -> 39
B74: 1 | C74: # 68710 | D74: black/red ribbons | F74: Veriphone 900 | I74: Per Dozen | J74: 39 | K74: =B74*J74 -> 39
B75: 1 | C75: # 68705 | D75: purple ribbons | F75: Veriphone 900 | I75: Per Dozen | J75: 39 | K75: =B75*J75 -> 39
...

Sheet EQUIP
B1: Qty | D1: Equipment (Taxable) | J1: Price | K1: Ext
C3: Note: The following are the standard, everyday unit pricing for each individual item.
C4: Discounts are available when compiling a quote for a full system with many components.
C5: Please seek assistance in preparing such a full system quote
C7: NCC embedded POS Workstations (does not include sw)
B8: 1 | C8: NCC /CRS Touchscreen station, embedded | J8: 1095 | K8: =B8*J8 -> 1095
B9: 1 | C9: NCC / Acrobat Touchscreen station, embedded | J9: 1095 | K9: =B9*J9 -> 1095
B11: 1 | C11: NCC Reflections R4 POS software (purchase option) | J11: 650 | K11: =B11*J11 -> 650
B12: 1 | C12: NCC Reflections R4 EFT Interface (purchase option) | J12: 475 | K12: =B12*J12 -> 475
B14: 1 | C14: NCC Retail Bundle, inc WS, Prt, Cd, Scan,POS sw, Msr, Std Database | J14: 2995 | K14: =B14*J14 -> 2995
B15: 1 | C15: NCC Hosp Bundle, inc WS, Prt, Cd ,Rkp, POS sw, Msr, Std Database | J15: 2995 | K15: =B15*J15 -> 2995
B17: 1 | C17: NCC SPT 45/47 workstation, with R4 software, reconditioned | J17: 695 | K17: =B17*J17 -> 695
B18: 1 | C18: NCC SPT3000 15" POS workstation, inc msr & POS SW, reconditioned | J18: 695 | K18: =B18*J18 -> 695
B19: 1 | C19: NCC BREEZE 15" POS workstation, inc msr & POS SW, reconditioned | J19: 695 | K19: =B19*J19 -> 695
B20: 1 | C20: NCC Acrobat POS workstation, inc msr & POS SW, reconditioned | J20: 695 | K20: =B20*J20 -> 695
B21: 1 | C21: NCC 5700 15" POS workstation, inc msr & POS SW, reconditioned | J21: 695 | K21: =B21*J21 -> 695
B22: 1 | C22: NCC Protech 10" POS workstation, inc msr & POS SW, reconditioned | J22: 695 | K22: =B22*J22 -> 695
B24: 1 | C24: Trade-In Credit for NCC workstation, repairable condition | J24: -325 | K24: =B24*J24 -> -325
C27: Windows POS Workstations ( does not include software)
B29: 1 | C29: Partnertech SP850 POS workstation, Win 10 | J29: 1695 | K29: =B29*J29 -> 1695
B30: 1 | C30: PAR 6155 Landscape workstation, Win 10 | J30: 1495 | K30: =B30*J30 -> 1495
B31: 1 | C31: CRS Windows Touchscreen station, Win 10 | J31: 1295 | K31: =B31*J31 -> 1295
B33: 1 | C33: CAS RX-750 POS workstation, reconditioned, POS Ready 7 | J33: 695 | K33: =B33*J33 -> 695
B34: 1 | C34: SHARP RX-650 POS workstation, reconsitioned, POS Ready 9 | J34: 495 | K34: =B34*J34 -> 495
B35: 1 | C35: PARTNERTECH SP800, reconditioned, POS Ready 7 | J35: 695 | K35: =B35*J35 -> 695
B36: 1 | C36: PIONEER WORKSTATION, reconditioned, POS Ready 7 | J36: 695 | K36: =B36*J36 -> 695
B38: 1 | C38: Swap Credit for Windows POS Ready 7 workstation, repairable | J38: -325 | K38: =B38*J38 -> -325
B39: 1 | C39: Swap Credit for Windows POS Ready 9 workstation, repairable | J39: -100 | K39: =B39*J39 -> -100
C41: Windows POS Tablets ( does not include software)
B42: 1 | C42: NCC Hisense Tablet station, Windows w/strap | J42: 995 | K42: =B42*J42 -> 995
B43: 1 | C43: NCC Hisense Tablet- docking station | J43: 195 | K43: =B43*J43 -> 195
B44: 1 | C44: NCC Hisense Tablet- add scanner | J44: 195 | K44: =B44*J44 -> 195
B46: 1 | C46: Touchdynamic Quest Tablet Station, Windows, w/strap | J46: 1495 | K46: =B46*J46 -> 1495
B47: 1 | C47: Touchdynamic Quest - Docking Station | J47: 295 | K47: =B47*J47 -> 295
B48: 1 | C48: Touchdynamic Quest - Add EMV | J48: 295 | K48: =B48*J48 -> 295
B49: 1 | C49: Touchdynamic Quest - Add Scanner | J49: 195 | K49: =B49*J49 -> 195
C52: POS Printers
B54: 1 | C54: SNBC Thermal Receipt Printer, serial / USB/ ether | J54: 250 | K54: =B54*J54 -> 250
B55: 1 | C55: Epson TMT88 VI thermal receipt printer, serial / usb/ ether | J55: 325 | K55: =B55*J55 -> 325
B57: 1 | C57: Epson TMU220b SERIAL impact remote printer (cut) | J57: 295 | K57: =B57*J57 -> 295
...

Sheet SOFTWARE
B1: Qty | D1: SOFTWARE (Taxable) | J1: Price | K1: Ext
C3: Note: The following are the standard, everyday unit pricing for each individual item.
C4: Discounts are available when compiling a quote for a full system with many components.
C5: Please seek assistance in preparing such a full system quote
C7: NCC SW MONTHLY
B9: 1 | C9: NCC Reflections R4 POS software, Per lane, per month | J9: 29 | K9: =B9*J9 -> 29
B10: 1 | C10: NCC Reflections EFT Payments Interface, Per lane, per month | J10: 29 | K10: =B10*J10 -> 29
B11: 1 | C11: NCC PCWS back office software, per month | J11: 29 | K11: =B11*J11 -> 29
B13: 1 | C13: NCC RHQ cloud reporting software, billed by NCC @ $50/mo/store | J13: 50 | K13: =B13*J13 -> 50
B15: 1 | C15: NCC INSIGHT management software ( includes PCWS) | J15: 125 | K15: =B15*J15 -> 125
C17: Maitre'd SW MONTHLY
B20: 1 | C20: MAITRE'D POS software, per WS 1-3, inc EFT, Gift, per month | J20: 69 | K20: =B20*J20 -> 69
B21: 1 | C21: MAITRE'D POS software, per WS 4-9, inc EFT, Gift, per month | J21: 49 | K21: =B21*J21 -> 49
B23: 1 | C23: MAITRE'D POS software, up to 4 workstations, inc EFT, Gift, per month | J23: 199 | K23: =B23*J23 -> 199
B24: 1 | C24: MAITRE'D POS software, MAX workstations, inc EFT, Gift, per month | J24: 299 | K24: =B24*J24 -> 299
B26: 1 | C26: MAITRE'D MPOS software, per Mobile Tablet,, inc EFT, Gift, per month | J26: 29 | K26: =B26*J26 -> 29
B28: 1 | C28: MAITRE'D Add-On Modules Package, per store, per month | J28: 49 | K28: =B28*J28 -> 49
C29: inc. PAT, cloud app, T/A, Acct, House, Hotel, Delivery, CCM, Scale
B31: 1 | C31: MAITRE'D Enterprise Management Corp Software, per store, per month | J31: TBD | K31: TBD
C34: Brink SW MONTHLY
B36: 1 | C36: BRINK POS Software, Ws #1, per month | J36: 90 | K36: =B36*J36 -> 90
B37: 1 | C37: BRINK POS Software, Ws # 2-4, per month | J37: 50 | K37: =B37*J37 -> 50
B38: 1 | C38: BRINK POS Software, Ws # 5-10, per month | J38: 30 | K38: =B38*J38 -> 30
B39: 1 | C39: BRINK POS Software, Ws #11+ , per month | J39: 20 | K39: =B39*J39 -> 20
C41: ( Note: Brink requires initial setup fee of $ 250 per store)
B43: 1 | C43: BRINK PAR PAY Software, First station , per month | J43: 39 | K43: =B43*J43 -> 39
B44: 1 | C44: BRINK PAR PAY Software, 2- x station , per month | J44: 15 | K44: =B44*J44 -> 15
C46: ( Par Pay requires initial setup fee of $ 175 per pinpad + cost of pinpad)
B48: 1 | C48: BRINK Kitchen Video Software, per station, per month | J48: 20 | K48: =B48*J48 -> 20
B50: 1 | C50: BRINK Future Date Ordering Software, per store, per month | J50: 15 | K50: =B50*J50 -> 15
B52: 1 | C52: BRINK Loyalty Software, per store, per month | J52: 75 | K52: =B52*J52 -> 75
B54: 1 | C54: BRINK POS Survey Software, per store, per month | J54: 15 | K54: =B54*J54 -> 15
B56: 1 | C56: BRINK Online Ordering 0-250 orders per month | J56: 75 | K56: =B56*J56 -> 75
B57: 1 | C57: BRINK Online Ordering 250-500 orders per month | J57: 125 | K57: =B57*J57 -> 125
B58: 1 | C58: BRINK Online Ordering 500-1000 orders per month | J58: 200 | K58: =B58*J58 -> 200
B59: 1 | C59: BRINK Online Ordering 1000-1500 orders per month | J59: 250 | K59: =B59*J59 -> 250
B60: 1 | C60: BRINK Online Ordering 1500-2000 orders per month | J60: 300 | K60: =B60*J60 -> 300
B61: 1 | C61: BRINK Online Ordering 2000-2500 orders per month | J61: 350 | K61: =B61*J61 -> 350
C64: Office/ Misc SW
B66: 1 | C66: Microsoft Windows 10 Pro | J66: 295 | K66: =B66*J66 -> 295
...

Sheet PARTS
B1: Qty | D1: Taxable Items | J1: Price | K1: Ext
C4: POS Printer Parts
B6: 1 | C6: External Power Supply | J6: 59 | K6: =B6*J6 -> 59
B7: 1 | C7: Thermal Print Head | J7: 95 | K7: =B7*J7 -> 95
B8: 1 | C8: Impact Dot Head | J8: 75 | K8: =B8*J8 -> 75
B9: 1 | C9: Printer Interface Card- Serial/Parallel | J9: 45 | K9: =B9*J9 -> 45
B10: 1 | C10: Printer Interface Card- Ethernet | J10: 95 | K10: =B10*J10 -> 95
B11: 1 | C11: External Plastic Casing | J11: 45 | K11: =B11*J11 -> 45
B12: 1 | C12: Printer Feed Assembly/Rollers | J12: 45 | K12: =B12*J12 -> 45
B13: 1 | C13: Printer Cutter Assembly | J13: 95 | K13: =B13*J13 -> 95
B14: 1 | C14: Printer Main CPU Board | J14: 95 | K14: =B14*J14 -> 95
C16: POS Workstation/PC Parts
B18: 1 | C18: Touchscreen- 15" | J18: 275 | K18: =B18*J18 -> 275
B19: 1 | C19: Touchscreen Assembly- Acrobat 14" | J19: 325 | K19: =B19*J19 -> 325
B20: 1 | C20: Touchscreen- 10" or 12" | J20: 195 | K20: =B20*J20 -> 195
B22: 1 | C22: External Power Supply- Workstation | J22: 75 | K22: =B22*J22 -> 75
B23: 1 | C23: Internal Power Supply | J23: 65 | K23: =B23*J23 -> 65
K24: =B24*J24 -> 0
B25: 1 | C25: Hard Drive | J25: 150 | K25: =B25*J25 -> 150
B26: 1 | C26: Ram Memory Chip | J26: 75 | K26: =B26*J26 -> 75
B27: 1 | C27: Compact Flash Card ( no sw) | J27: 45 | K27: =B27*J27 -> 45
B28: 1 | C28: Fan- PC/POS | J28: 45 | K28: =B28*J28 -> 45
B29: 1 | C29: Power Distribution Board | J29: 75 | K29: =B29*J29 -> 75
B30: 1 | C30: LCD Invertor | J30: 75 | K30: =B30*J30 -> 75
B31: 1 | C31: LCD Backlights | J31: 75 | K31: =B31*J31 -> 75
B32: 1 | C32: LCD Full assembly | J32: 375 | K32: =B32*J32 -> 375
B33: 1 | C33: Network Card | J33: 50 | K33: =B33*J33 -> 50
B34: 1 | C34: Main CPU Board Replace | J34: 295 | K34: =B34*J34 -> 295
B35: 1 | C35: Capacitor/Resistor/Transistor | J35: 5 | K35: =B35*J35 -> 5
B36: 1 | C36: CMOS Battery | J36: 25 | K36: =B36*J36 -> 25
... B45: 1 | C45: NCR WS RJ11- RJ45 Serial Port Adaptor | J45: 22.5 | K45: =B45*J45 -> 22.5
C47: Power Conditioner/UPS
B49: 1 | C49: Replacement Battery Set for UPS | J49: 95 | K49: =B49*J49 -> 95
B50: 1 | C50: Replacement Housing Panel- Oneac | J50: 19.5 | K50: =B50*J50 -> 19.5
C52: Cash Drawers
B54: 1 | C54: Replacement Cash Drawer, reconditioned (no till) | J54: 75 | K54: =B54*J54 -> 75
B55: 1 | C55: Replacement Cash Drawer, reconditioned (with till) | J55: 95 | K55: =B55*J55 -> 95
B56: 1 | C56: Epson Cash Drawer interface cable | J56: 9.5 | K56: =B56*J56 -> 9.5
B57: 1 | C57: Sharp Cash Drawer interface cable | J57: 9.5 | K57: =B57*J57 -> 9.5
B58: 1 | C58: Casio Cash Drawer interface cable | J58: 15 | K58: =B58*J58 -> 15
...

Sheet LABOR
B1: Qty | D1: Description | J1: Price | K1: Ext
B4: Labor Billing:
E5: Description: | J5: Hrly Rate
B6: 1 | C6: in-shop labor, business hours M-F | J6: 180 | K6: =SUM(B6*J6) -> 180
B7: 1 | C7: on-site labor, business hours M-F | J7: 180 | K7: =SUM(B7*J7) -> 180
B9: 1 | C9: in-shop labor- after hours rate | J9: 270 | K9: =SUM(B9*J9) -> 270
B10: 1 | C10: on-site labor- after hours rate | J10: 270 | K10: =SUM(B10*J10) -> 270
B12: 1 | C12: Minimum In-Shop Labor Rate, up to 30min | K12: 90
B13: 1 | C13: Minimum Business Hours Phone Support, up to 15min | K13: 45
B14: 1 | C14: Minimum After Hours Phone Support, up to 15min | K14: 75
B16: 1 | C16: Pickup/Delivery/Drop Off Fee | K16: 90
B18: 0.5 | C18: Travel Time | J18: 180 | K18: =SUM(B18*J18) -> 90
B20: 1 | C20: discount on hourly labor- BOH | J20: -60 | K20: =SUM(B20*J20) -> -60
B21: 1 | C21: discount on travel- BOH | J21: -30 | K21: =SUM(B21*J21) -> -30
B24: Installation Billing:
E25: Description: | J25: Rate
B26: 1 | C26: in-shop setup of POS, per station | J26: 75 | K26: =B26*J26 -> 75
B27: 1 | C27: in-shop initial setup/program of cash register | J27: 90 | K27: =B27*J27 -> 90
B28: 1 | C28: in-shop initial menu programming for NCC | J28: 480 | K28: =B28*J28 -> 480
B29: 1 | C29: in-shop initial menu programming for Maitre'd | J29: 960 | K29: =B29*J29 -> 960
B30: 1 | C30: in-shop initial menu programming for Brink | J30: 960 | K30: =B30*J30 -> 960
B31: 1 | C31: delivery, installation, per workstation | J31: 150 | K31: =B31*J31 -> 150
C32: Note: Client to provide adequate counters, electrical, net. cabling, internet
B33: 1 | C33: Training class , up to four hours ea | J33: 480 | K33: =B33*J33 -> 480
B34: 1 | C34: Discounted Day Rate for training, standby, or installation services | J34: 720 | K34: =B34*J34 -> 720
B35: 1 | C35: Post install followup training and/or add-on module implementation | J35: 360 | K35: =B35*J35 -> 360
B39: Help Desk Billing:
E40: Description: | J40: Rate
C41: Help Desk - Business Hours
B43: 1 | C43: Annual POS system Help Desk Support- Level One- NCC | J43: 500 | K43: =J43*B43 -> 500
B44: 1 | C44: Monthly POS system Help Desk Support- Level One- NCC | J44: 49 | K44: =J44*B44 -> 49
B46: 1 | C46: Annual POS system Help Desk Support- Level One- Maitre'd | J46: 600 | K46: =J46*B46 -> 600
B47: 1 | C47: MonthlyPOS system Help Desk Support- Level One- Maitre'd | J47: 69 | K47: =J47*B47 -> 69
C49: Allows for unlimited calls Mon-Fri business hours for routine operational
C50: software assistance and troubleshooting.
C51: Does not cover new manager training or significant system re-programming | K51: =J51*B51 -> 0
C53: Help Desk 7 x 24
B55: 1 | C55: Annual POS system Help Desk Support- Level Two- NCC | J55: 750 | K55: =J55*B55 -> 750
B56: 1 | C56: Monthly POS system Help Desk Support- Level Two- NCC | J56: 69 | K56: =J56*B56 -> 69
B58: 1 | C58: Annual POS system Help Desk Support- Level Two- Maitre'd | J58: 900 | K58: =J58*B58 -> 900
...

Sheet MAINT
B1: Qty | D1: Service Contracts | J1: Price | K1: Ext
C3: All support plan options listed below are at standard pricing, payable upon receipt
C4: All support plans are auto-renewing until cancelled by client.
C5: No pro-rated refunds for unused periods
E7: Description: | J7: Rate
C8: Help Desk - Business Hours
B10: 1 | C10: Annual POS system Help Desk Support- Level One- NCC | J10: 500 | K10: =J10*B10 -> 500
B11: 1 | C11: Monthly POS system Help Desk Support- Level One- NCC | J11: 49 | K11: =J11*B11 -> 49
B13: 1 | C13: Annual POS system Help Desk Support- Level One- Maitre'd | J13: 600 | K13: =J13*B13 -> 600
B14: 1 | C14: MonthlyPOS system Help Desk Support- Level One- Maitre'd | J14: 69 | K14: =J14*B14 -> 69
C16: Allows for unlimited calls Mon-Fri business hours for routine operational
C17: software assistance and troubleshooting.
C18: Does not cover new manager training or significant system re-programming | K18: =J18*B18 -> 0
C20: Help Desk 7 x 24
B22: 1 | C22: Annual POS system Help Desk Support- Level Two- NCC | J22: 750 | K22: =J22*B22 -> 750
B23: 1 | C23: Monthly POS system Help Desk Support- Level Two- NCC | J23: 69 | K23: =J23*B23 -> 69
B25: 1 | C25: Annual POS system Help Desk Support- Level Two- Maitre'd | J25: 900 | K25: =J25*B25 -> 900
B26: 1 | C26: Monthly POS system Help Desk Support- Level Two-- Maitre'd | J26: 89 | K26: =J26*B26 -> 89
C29: Allows for unlimited calls Mon-Sun 7 x 24 hour for routine operational
C30: software assistance and troubleshooting.
C31: Does not cover new manager training or significant system re-programming | K31: =J31*B31 -> 0
C34: Annual POS Hardware Depot Repair Coverage
B36: 1 | C36: Office Server + peripherals | J36: 250 | K36: =B36*J36 -> 250
B37: 1 | C37: Workstations+ peripherals | J37: 250 | K37: =B37*J37 -> 250
B38: 1 | C38: Monthly Depot Repair Coverage, per workstation, 12 mo min | J38: 25 | K38: =B38*J38 -> 25
C40: Note: Client pays to ship to repair center, Performance pays to ship back ground
C41: Coverage applies to wear & tear resulting from normal operation of equipment
C43: Annual POS Hardware Onsite Repair Coverage- SF BAY Area only
B45: 1 | C45: Office Server + peripherals | J45: 500 | K45: =B45*J45 -> 500
B46: 1 | C46: Workstations+ peripherals | J46: 500 | K46: =B46*J46 -> 500
B47: 1 | C47: Monthly Onsite Repair Coverage, per workstation, 12 month min | J47: 49 | K47: =B47*J47 -> 49
C49: Note: All work to be performed during bus.hours M-F
C50: Coverage applies to wear & tear resulting from normal operation of equipment

Sheet TAX RATES 2020
A1: All Cities
A3: Effective April 1, 2019
A5: * Indicates incorporated city or incorporated town
A7: City | B7: Rate | C7: County
A9: Acampo | B9: 0.0775 | C9: San Joaquin
A10: Acton | B10: 0.095 | C10: Los Angeles
A11: Adelaida | B11: 0.0725 | C11: San Luis Obispo
A12: Adelanto* | B12: 0.0775 | C12: San Bernardino
A13: Adin | B13: 0.0725 | C13: Modoc
A14: Agoura | B14: 0.095 | C14: Los Angeles
A15: Agoura Hills* | B15: 0.095 | C15: Los Angeles
A16: Agua Caliente | B16: 0.0825 | C16: Sonoma
A17: Agua Caliente Springs | B17: 0.0775 | C17: San Diego
A18: Agua Dulce | B18: 0.095 | C18: Los Angeles
A19: Aguanga | B19: 0.0775 | C19: Riverside
A20: Ahwahnee | B20: 0.0775 | C20: Madera
... A1793: Zenia | B1793: 0.0725 | C1793: Trinity

Sheet EMPLOYEES
A1: Performance POS 415-451-4861 100-A Pelican Way, San Rafael CA 94901
A2: Toll-Free Support: 888-411-3375 support@performancepos.com
A3: Toll-Free Supplies: 800-581-2274 supplies@performancepos.com
A4: Fax 415-451-4866
A5: Employee | C5: Ext | D5: Desk | E5: Cell | F5: Email
A6: Angel Solorzano | B6: AS | C6: 1019 | D6: 415-960-3270 | E6: 908-357-8442 | F6: angel@performancepos.com
A7: Antonio Hudnall | B7: AH | C7: 1009 | E7: 415-532-6834 | F7: antonio@performancepos.com
A8: Dennis Fees | B8: DF | C8: 1012 | D8: 415-688-2721 | E8: 415-515-2483 | F8: dennisfees@performancepos.com
A9: Denny Deyerle | B9: DD | C9: 1010 | D9: 415-688-2602 | E9: 925-956-9245 | F9: denny@performancepos.com
A10: Doug Kelly | B10: DK | C10: 1005 | D10: 415-688-2354 | E10: 415-432-0630 | F10: dougkelly@performancepos.com
A11: Eltjon Lala | B11: EL | C11: 1015 | D11: 415-688-2724 | E11: 978-608-3975 | F11: eltjon@performancepos.com
A12: Jose Santos | B12: JS | C12: 1007 | D12: 415-688-2358 | E12: 415-747-2564 | F12: josesantos@performancepos.com
A13: Lowell Galang | B13: LG | C13: 1016 | D13: 415-870-2036 | E13: 650-278-2997 | F13: lgalang@performancepos.com
A14: Milton Bland | B14: MB | C14: 1006 | D14: 415-688-2357 | E14: 415-747-0039 | F14: milton@performancepos.com
A15: Nikaela King | B15: NK | C15: 1018 | D15: 415-960-3272 | E15: 510-323-5209 | F15: nikaela@performancepos.com
A16: Rich Alden | B16: RA | C16: 1008 | D16: 415-688-2599 | E16: 415-747-0038 | F16: richalden@performancepos.com
A17: Rob Freaney | B17: RF | C17: 1001 | D17: 415-688-2348 | E17: 415-747-2568 | F17: robfreaney@performancepos.com
A18: Sandy Gonzalez | B18: SG | C18: 1011 | D18: 415-688-2603 | E18: 415-312-4175 | F18: sandy@performancepos.com
A19: Showroom | C19: 1004
A20: Shipping Desk | C20: 1013
A21: Install Room | C21: 1014
A23: Outside Tech Resources
A25: Pete Pizzino | B25: PP | D25: 510-506-6316 | F25: cashreg@sbcglobal.net
A26: Alain Rousseau | B26: AR | D26: 514-730-9995 | F26: arousseau2020@gmail.com
A27: POS & ECR
A28: NCC & RHQ | D28: 866-944-5164 | F28: nccusa.com & nccusa.com/rhq
A29: Posera Maitre'd | D29: 888-404-2662 | F29: distributors.maitredpos.com
A30: Casio | D30: 800-633-5586 | F30: casio.com
A31: Credit Cards
A32: Datacap | D32: 215-997-8989 | F32: datacapsystems.com
A33: Mercury Vantiv | D33: 800-846-4472 | F33: techsupport@mercurypay.com
A34: Sterling | D34: 800-591-6098 | F34: sterlingpayment.com
